Workbook
Name Lake: PC!$B$467
Name b: 'Master List'!$A:$A
Name dragon: 'Master List'!$A$1661
Name assass: 'Master List'!$A$872
Name onrush: 'Master List'!$A$1157
Name Tiny: 'Xbox Game Studios'!$A$1
Name civ: PC!$A$1
Name gris: 'Master List'!$A$1564
Name PC: 'Master List'!$A$2
Name hellslinger: xCloud!$K$85
Name chain: 'Master List'!$A$1
Name persona: Removed!$H$288:$H$295
Name banjo: Removed!$I$110
Name banjo: 'Master List'!$I$1186
Name YEARDUR: LAMBDA(start, end, lambda(s, e, if(s > e, -1 , 1 ) * yearfrac(s, e, 4))(if(isblank(start),today(),start), if(isblank(end),today(),end)))
Name MONTHDUR: LAMBDA(start, end, YEARDUR(start, end) * 12)

Sheet Master List
A1: Complete Game Pass Master List by u/ABattleVet | B1: =COUNTIFS(D2:D2121,"Active",B2:B2121,"<>")+COUNTIF(D2:D2121,"Leaving Soon") -> 687 | C1: Games with Gold | E1: GPU | H1: Playstation Plus | L1: See suggestions tab for color coding | N1: The community can add games to cross play/play anywhere | P1: Public Notes | R1: GP Premium (10/1/25 Standard 9/12/24)
A2: Game | B2: System | C2: xCloud | D2: Status | E2: Added | F2: Removed | G2: Months | H2: Release | I2: Age | J2: Metacritic | K2: Completion | L2: Genre | M2: Series X|S | N2: Owner Notes | O2: ESRB | P2: ESRB Content Descriptors | Q2: Community Notes | R2: Status | S2: Added | T2: Delay
A3: The Outer Worlds 2 | B3: Xbox / PC | C3: Yes | D3: =IF(E3>TODAY(),"Coming Soon",IF(F3="","Active",IF(F3>TODAY(),"Leaving Soon","Removed"))) -> Coming Soon | E3: 45959 | G3: =MONTHDUR(E3,F3) -> -0.46666667 | H3: =E3 -> 45959 | I3: =YEARDUR(H3,E3) -> 0 | L3: RPG | M3: Exclusive | R3: =IF(S3="","TBD",IF(S3>TODAY(),"Coming Soon",IF(F3="","Active",IF(F3>TODAY(),"Leaving Soon","Removed")))) -> TBD | T3: =MONTHDUR(E3,S3) -> -0.46666667
A4: Evil West | B4: Xbox / PC | C4: Yes | D4: =IF(E4>TODAY(),"Coming Soon",IF(F4="","Active",IF(F4>TODAY(),"Leaving Soon","Removed"))) -> Coming Soon | E4: 45951 | G4: =MONTHDUR(E4,F4) -> -0.2 | H4: 44887 | I4: =YEARDUR(H4,E4) -> 2.9138889 | J4: 73 | K4: 11 | L4: Shooter | N4: Returning title: Joined 3/21/24, left 3/15/25 | O4: M | P4: Blood and Gore, Intense Violence, Strong Language | R4: =IF(S4="","TBD",IF(S4>TODAY(),"Coming Soon",IF(F4="","Active",IF(F4>TODAY(),"Leaving Soon","Removed")))) -> Active | S4: 45547 | T4: =MONTHDUR(E4,S4) -> -13.3
A5: Ninja Gaiden 4 | B5: Xbox / PC | C5: Yes | D5: =IF(E5>TODAY(),"Coming Soon",IF(F5="","Active",IF(F5>TODAY(),"Leaving Soon","Removed"))) -> Coming Soon | E5: 45951 | G5: =MONTHDUR(E5,F5) -> -0.2 | H5: =E5 -> 45951 | I5: =YEARDUR(H5,E5) -> 0 | L5: Action-Adventure | M5: Exclusive | R5: =IF(S5="","TBD",IF(S5>TODAY(),"Coming Soon",IF(F5="","Active",IF(F5>TODAY(),"Leaving Soon","Removed")))) -> TBD | T5: =MONTHDUR(E5,S5) -> -0.2
A6: Keeper | B6: Xbox / PC | C6: Yes | D6: =IF(E6>TODAY(),"Coming Soon",IF(F6="","Active",IF(F6>TODAY(),"Leaving Soon","Removed"))) -> Coming Soon | E6: 45947 | G6: =MONTHDUR(E6,F6) -> -0.066666667 | H6: =E6 -> 45947 | I6: =YEARDUR(H6,E6) -> 0 | L6: Action-Adventure | M6: Exclusive | R6: =IF(S6="","TBD",IF(S6>TODAY(),"Coming Soon",IF(F6="","Active",IF(F6>TODAY(),"Leaving Soon","Removed")))) -> TBD | T6: =MONTHDUR(E6,S6) -> -0.066666667
A7: Pax Dei | B7: PC | D7: =IF(E7>TODAY(),"Coming Soon",IF(F7="","Active",IF(F7>TODAY(),"Leaving Soon","Removed"))) -> Coming Soon | E7: 45946 | G7: =MONTHDUR(E7,F7) -> -0.033333333 | H7: =E7 -> 45946 | I7: =YEARDUR(H7,E7) -> 0 | L7: RPG | R7: =IF(S7="","TBD",IF(S7>TODAY(),"Coming Soon",IF(F7="","Active",IF(F7>TODAY(),"Leaving Soon","Removed")))) -> TBD | T7: =MONTHDUR(E7,S7) -> -0.033333333
A8: Ball x Pit | B8: Xbox / PC | C8: Yes | D8: =IF(E8>TODAY(),"Coming Soon",IF(F8="","Active",IF(F8>TODAY(),"Leaving Soon","Removed"))) -> Active | E8: 45945 | G8: =MONTHDUR(E8,F8) -> 0 | H8: =E8 -> 45945 | I8: =YEARDUR(H8,E8) -> 0 | L8: Shoot-'Em-Up | R8: =IF(S8="","TBD",IF(S8>TODAY(),"Coming Soon",IF(F8="","Active",IF(F8>TODAY(),"Leaving Soon","Removed")))) -> TBD | T8: =MONTHDUR(E8,S8) -> 0
A9: The Grinch: Christmas Adventures | B9: Xbox / PC | C9: Yes | D9: =IF(E9>TODAY(),"Coming Soon",IF(F9="","Active",IF(F9>TODAY(),"Leaving Soon","Removed"))) -> Active | E9: 45945 | G9: =MONTHDUR(E9,F9) -> 0 | H9: 45212 | I9: =YEARDUR(H9,E9) -> 2.0055556 | J9: =average(50,75,80) -> 68.333333 | K9: 3 | L9: Platformer | R9: =IF(S9="","TBD",IF(S9>TODAY(),"Coming Soon",IF(F9="","Active",IF(F9>TODAY(),"Leaving Soon","Removed")))) -> TBD | T9: =MONTHDUR(E9,S9) -> 0
A10: The Casting of Frank Stone | B10: Xbox / PC | C10: Yes | D10: =IF(E10>TODAY(),"Coming Soon",IF(F10="","Active",IF(F10>TODAY(),"Leaving Soon","Removed"))) -> Active | E10: 45944 | G10: =MONTHDUR(E10,F10) -> 0.033333333 | H10: 45538 | I10: =YEARDUR(H10,E10) -> 1.1138889 | J10: 68 | K10: 6 | L10: Action-Adventure | M10: Exclusive | R10: =IF(S10="","TBD",IF(S10>TODAY(),"Coming Soon",IF(F10="","Active",IF(F10>TODAY(),"Leaving Soon","Removed")))) -> TBD | T10: =MONTHDUR(E10,S10) -> 0.033333333
A11: Baldur's Gate and Baldur's Gate II: Enhanced Editions | B11: PC | D11: =IF(E11>TODAY(),"Coming Soon",IF(F11="","Active",IF(F11>TODAY(),"Leaving Soon","Removed"))) -> Active | E11: 45939 | G11: =MONTHDUR(E11,F11) -> 0.2 | H11: 43753 | I11: =YEARDUR(H11,E11) -> 5.9833333 | J11: 72 | K11: =31+45 -> 76 | L11: RPG | R11: =IF(S11="","TBD",IF(S11>TODAY(),"Coming Soon",IF(F11="","Active",IF(F11>TODAY(),"Leaving Soon","Removed")))) -> TBD | T11: =MONTHDUR(E11,S11) -> 0.2
A12: Little Rocket Lab | B12: Xbox / PC | C12: Yes | D12: =IF(E12>TODAY(),"Coming Soon",IF(F12="","Active",IF(F12>TODAY(),"Leaving Soon","Removed"))) -> Active | E12: 45938 | G12: =MONTHDUR(E12,F12) -> 0.23333333 | H12: 45937 | I12: =YEARDUR(H12,E12) -> 0.0027777778 | J12: 83 | L12: Sandbox | R12: =IF(S12="","TBD",IF(S12>TODAY(),"Coming Soon",IF(F12="","Active",IF(F12>TODAY(),"Leaving Soon","Removed")))) -> TBD | T12: =MONTHDUR(E12,S12) -> 0.23333333
A13: Supermarket Simulator | B13: Xbox / PC | C13: Yes | D13: =IF(E13>TODAY(),"Coming Soon",IF(F13="","Active",IF(F13>TODAY(),"Leaving Soon","Removed"))) -> Active | E13: 45938 | G13: =MONTHDUR(E13,F13) -> 0.23333333 | H13: 45827 | I13: =YEARDUR(H13,E13) -> 0.30277778 | L13: Simulation | R13: =IF(S13="","TBD",IF(S13>TODAY(),"Coming Soon",IF(F13="","Active",IF(F13>TODAY(),"Leaving Soon","Removed")))) -> TBD | T13: =MONTHDUR(E13,S13) -> 0.23333333
A14: Sopa: Tale of the Stolen Potato | B14: Xbox / PC | C14: Yes | D14: =IF(E14>TODAY(),"Coming Soon",IF(F14="","Active",IF(F14>TODAY(),"Leaving Soon","Removed"))) -> Active | E14: 45937 | G14: =MONTHDUR(E14,F14) -> 0.26666667 | H14: 45937 | I14: =YEARDUR(H14,E14) -> 0 | J14: 79 | K14: 3 | L14: Action-Adventure | R14: =IF(S14="","TBD",IF(S14>TODAY(),"Coming Soon",IF(F14="","Active",IF(F14>TODAY(),"Leaving Soon","Removed")))) -> TBD | T14: =MONTHDUR(E14,S14) -> 0.26666667
A15: Hogwarts Legacy | B15: Xbox / PC | C15: Yes | D15: =IF(E15>TODAY(),"Coming Soon",IF(F15="","Active",IF(F15>TODAY(),"Leaving Soon","Removed"))) -> Active | E15: 45931 | G15: =MONTHDUR(E15,F15) -> 0.46666667 | H15: 44964 | I15: =YEARDUR(H15,E15) -> 2.65 | J15: 84 | K15: 27 | L15: Action-Adventure | N15: Ubisoft games joining with price increase | R15: =IF(S15="","TBD",IF(S15>TODAY(),"Coming Soon",IF(F15="","Active",IF(F15>TODAY(),"Leaving Soon","Removed")))) -> Active | S15: 45931 | T15: =MONTHDUR(E15,S15) -> 0
A16: Assassin's Creed II | B16: PC | D16: =IF(E16>TODAY(),"Coming Soon",IF(F16="","Active",IF(F16>TODAY(),"Leaving Soon","Removed"))) -> Active | E16: 45931 | G16: =MONTHDUR(E16,F16) -> 0.46666667 | H16: 40134 | I16: =YEARDUR(H16,E16) -> 15.872222 | J16: 90 | K16: 19 | L16: Action-Adventure | N16: Ubisoft games joining with price increase | P16: 232 | R16: =IF(S16="","TBD",IF(S16>TODAY(),"Coming Soon",IF(F16="","Active",IF(F16>TODAY(),"Leaving Soon","Removed")))) -> TBD | T16: =MONTHDUR(E16,S16) -> 0.46666667
A17: Assassin's Creed III: Remastered | B17: Xbox / PC | C17: Yes | D17: =IF(E17>TODAY(),"Coming Soon",IF(F17="","Active",IF(F17>TODAY(),"Leaving Soon","Removed"))) -> Active | E17: 45931 | G17: =MONTHDUR(E17,F17) -> 0.46666667 | H17: 43553 | I17: =YEARDUR(H17,E17) -> 6.5055556 | J17: 72 | K17: 15 | L17: Action-Adventure | N17: Ubisoft games joining with price increase | R17: =IF(S17="","TBD",IF(S17>TODAY(),"Coming Soon",IF(F17="","Active",IF(F17>TODAY(),"Leaving Soon","Removed")))) -> TBD | T17: =MONTHDUR(E17,S17) -> 0.46666667
A18: Assassin's Creed IV Black Flag | B18: Xbox / PC | C18: Yes | D18: =IF(E18>TODAY(),"Coming Soon",IF(F18="","Active",IF(F18>TODAY(),"Leaving Soon","Removed"))) -> Active | E18: 45931 | G18: =MONTHDUR(E18,F18) -> 0.46666667 | H18: 41576 | I18: =YEARDUR(H18,E18) -> 11.922222 | J18: 88 | K18: 24 | L18: Action-Adventure | N18: Ubisoft games joining with price increase | R18: =IF(S18="","TBD",IF(S18>TODAY(),"Coming Soon",IF(F18="","Active",IF(F18>TODAY(),"Leaving Soon","Removed")))) -> TBD | T18: =MONTHDUR(E18,S18) -> 0.46666667
A19: Assassin's Creed IV Black Flag: Freedom Cry | B19: PC | D19: =IF(E19>TODAY(),"Coming Soon",IF(F19="","Active",IF(F19>TODAY(),"Leaving Soon","Removed"))) -> Active | E19: 45931 | G19: =MONTHDUR(E19,F19) -> 0.46666667 | H19: 41626 | I19: =YEARDUR(H19,E19) -> 11.786111 | J19: 71 | K19: 4 | L19: Action-Adventure | N19: Ubisoft games joining with price increase | R19: =IF(S19="","TBD",IF(S19>TODAY(),"Coming Soon",IF(F19="","Active",IF(F19>TODAY(),"Leaving Soon","Removed")))) -> TBD | T19: =MONTHDUR(E19,S19) -> 0.46666667
A20: Assassin's Creed Brotherhood | B20: PC | D20: =IF(E20>TODAY(),"Coming Soon",IF(F20="","Active",IF(F20>TODAY(),"Leaving Soon","Removed"))) -> Active | E20: 45931 | G20: =MONTHDUR(E20,F20) -> 0.46666667 | H20: 40498 | I20: =YEARDUR(H20,E20) -> 14.875 | J20: 89 | K20: 15 | L20: Action-Adventure | N20: Ubisoft games joining with price increase | R20: =IF(S20="","TBD",IF(S20>TODAY(),"Coming Soon",IF(F20="","Active",IF(F20>TODAY(),"Leaving Soon","Removed")))) -> TBD | T20: =MONTHDUR(E20,S20) -> 0.46666667
A21: Assassin's Creed Chronicles: China | B21: Xbox / PC | C21: Yes | D21: =IF(E21>TODAY(),"Coming Soon",IF(F21="","Active",IF(F21>TODAY(),"Leaving Soon","Removed"))) -> Active | E21: 45931 | G21: =MONTHDUR(E21,F21) -> 0.46666667 | H21: 42115 | I21: =YEARDUR(H21,E21) -> 10.444444 | J21: 69 | K21: 6 | L21: Action-Adventure | N21: Ubisoft games joining with price increase | R21: =IF(S21="","TBD",IF(S21>TODAY(),"Coming Soon",IF(F21="","Active",IF(F21>TODAY(),"Leaving Soon","Removed")))) -> TBD | T21: =MONTHDUR(E21,S21) -> 0.46666667
A22: Assassin's Creed Chronicles: India | B22: Xbox / PC | C22: Yes | D22: =IF(E22>TODAY(),"Coming Soon",IF(F22="","Active",IF(F22>TODAY(),"Leaving Soon","Removed"))) -> Active | E22: 45931 | G22: =MONTHDUR(E22,F22) -> 0.46666667 | H22: 42382 | I22: =YEARDUR(H22,E22) -> 9.7166667 | J22: 63 | K22: 6 | L22: Action-Adventure | N22: Ubisoft games joining with price increase | R22: =IF(S22="","TBD",IF(S22>TODAY(),"Coming Soon",IF(F22="","Active",IF(F22>TODAY(),"Leaving Soon","Removed")))) -> TBD | T22: =MONTHDUR(E22,S22) -> 0.46666667
A23: Assassin's Creed Chronicles: Russia | B23: Xbox / PC | C23: Yes | D23: =IF(E23>TODAY(),"Coming Soon",IF(F23="","Active",IF(F23>TODAY(),"Leaving Soon","Removed"))) -> Active | E23: 45931 | G23: =MONTHDUR(E23,F23) -> 0.46666667 | H23: 42409 | I23: =YEARDUR(H23,E23) -> 9.6444444 | J23: 62 | K23: 7 | L23: Action-Adventure | N23: Ubisoft games joining with price increase | R23: =IF(S23="","TBD",IF(S23>TODAY(),"Coming Soon",IF(F23="","Active",IF(F23>TODAY(),"Leaving Soon","Removed")))) -> TBD | T23: =MONTHDUR(E23,S23) -> 0.46666667
A24: Assassin's Creed Liberation HD | B24: PC | D24: =IF(E24>TODAY(),"Coming Soon",IF(F24="","Active",IF(F24>TODAY(),"Leaving Soon","Removed"))) -> Active | E24: 45931 | G24: =MONTHDUR(E24,F24) -> 0.46666667 | H24: 41654 | I24: =YEARDUR(H24,E24) -> 11.711111 | J24: 62 | K24: 8 | L24: Action-Adventure | N24: Ubisoft games joining with price increase | R24: =IF(S24="","TBD",IF(S24>TODAY(),"Coming Soon",IF(F24="","Active",IF(F24>TODAY(),"Leaving Soon","Removed")))) -> TBD | T24: =MONTHDUR(E24,S24) -> 0.46666667
A25: Assassin's Creed Revelations | B25: PC | D25: =IF(E25>TODAY(),"Coming Soon",IF(F25="","Active",IF(F25>TODAY(),"Leaving Soon","Removed"))) -> Active | E25: 45931 | G25: =MONTHDUR(E25,F25) -> 0.46666667 | H25: 40862 | I25: =YEARDUR(H25,E25) -> 13.877778 | J25: 80 | K25: 13 | L25: Action-Adventure | N25: Ubisoft games joining with price increase | R25: =IF(S25="","TBD",IF(S25>TODAY(),"Coming Soon",IF(F25="","Active",IF(F25>TODAY(),"Leaving Soon","Removed")))) -> TBD | T25: =MONTHDUR(E25,S25) -> 0.46666667
A26: Assassin's Creed Rogue: Remastered | B26: Xbox / PC | C26: Yes | D26: =IF(E26>TODAY(),"Coming Soon",IF(F26="","Active",IF(F26>TODAY(),"Leaving Soon","Removed"))) -> Active | E26: 45931 | G26: =MONTHDUR(E26,F26) -> 0.46666667 | H26: 43179 | I26: =YEARDUR(H26,E26) -> 7.5305556 | J26: 71 | K26: 11 | L26: Action-Adventure | N26: Ubisoft games joining with price increase | R26: =IF(S26="","TBD",IF(S26>TODAY(),"Coming Soon",IF(F26="","Active",IF(F26>TODAY(),"Leaving Soon","Removed")))) -> TBD | T26: =MONTHDUR(E26,S26) -> 0.46666667
A27: Assassin's Creed Syndicate | B27: Xbox / PC | C27: Yes | D27: =IF(E27>TODAY(),"Coming Soon",IF(F27="","Active",IF(F27>TODAY(),"Leaving Soon","Removed"))) -> Active | E27: 45931 | G27: =MONTHDUR(E27,F27) -> 0.46666667 | H27: 42300 | I27: =YEARDUR(H27,E27) -> 9.9388889 | J27: 76 | K27: 19 | L27: Action-Adventure | N27: Ubisoft games joining with price increase | R27: =IF(S27="","TBD",IF(S27>TODAY(),"Coming Soon",IF(F27="","Active",IF(F27>TODAY(),"Leaving Soon","Removed")))) -> TBD | T27: =MONTHDUR(E27,S27) -> 0.46666667
A28: Assassin's Creed: The Ezio Collection | B28: Xbox | C28: Yes | D28: =IF(E28>TODAY(),"Coming Soon",IF(F28="","Active",IF(F28>TODAY(),"Leaving Soon","Removed"))) -> Active | E28: 45931 | G28: =MONTHDUR(E28,F28) -> 0.46666667 | H28: 42689 | I28: =YEARDUR(H28,E28) -> 8.8777778 | J28: 72 | K28: 72 | L28: Action-Adventure | N28: Ubisoft games joining with price increase | R28: =IF(S28="","TBD",IF(S28>TODAY(),"Coming Soon",IF(F28="","Active",IF(F28>TODAY(),"Leaving Soon","Removed")))) -> TBD | T28: =MONTHDUR(E28,S28) -> 0.46666667
A29: Assassin's Creed Unity | B29: Xbox / PC | C29: Yes | D29: =IF(E29>TODAY(),"Coming Soon",IF(F29="","Active",IF(F29>TODAY(),"Leaving Soon","Removed"))) -> Active | E29: 45931 | G29: =MONTHDUR(E29,F29) -> 0.46666667 | H29: 41954 | I29: =YEARDUR(H29,E29) -> 10.888889 | J29: 72 | K29: 17 | L29: Action-Adventure | N29: Ubisoft games joining with price increase | R29: =IF(S29="","TBD",IF(S29>TODAY(),"Coming Soon",IF(F29="","Active",IF(F29>TODAY(),"Leaving Soon","Removed")))) -> TBD | T29: =MONTHDUR(E29,S29) -> 0.46666667
A30: Child of Light | B30: Xbox / PC | C30: Yes | D30: =IF(E30>TODAY(),"Coming Soon",IF(F30="","Active",IF(F30>TODAY(),"Leaving Soon","Removed"))) -> Active | E30: 45931 | G30: =MONTHDUR(E30,F30) -> 0.46666667 | H30: 41758 | I30: =YEARDUR(H30,E30) -> 11.422222 | J30: 82 | K30: 11 | L30: RPG | N30: Ubisoft games joining with price increase | R30: =IF(S30="","TBD",IF(S30>TODAY(),"Coming Soon",IF(F30="","Active",IF(F30>TODAY(),"Leaving Soon","Removed")))) -> TBD | T30: =MONTHDUR(E30,S30) -> 0.46666667
A31: Far Cry 3 | B31: Xbox / PC | C31: Yes | D31: =IF(E31>TODAY(),"Coming Soon",IF(F31="","Active",IF(F31>TODAY(),"Leaving Soon","Removed"))) -> Active | E31: 45931 | G31: =MONTHDUR(E31,F31) -> 0.46666667 | H31: 41247 | I31: =YEARDUR(H31,E31) -> 12.825 | J31: 88 | K31: 16 | L31: Action-Adventure | N31: Ubisoft games joining with price increase | R31: =IF(S31="","TBD",IF(S31>TODAY(),"Coming Soon",IF(F31="","Active",IF(F31>TODAY(),"Leaving Soon","Removed")))) -> TBD | T31: =MONTHDUR(E31,S31) -> 0.46666667
A32: Far Cry 3: Blood Dragon | B32: Xbox / PC | C32: Yes | D32: =IF(E32>TODAY(),"Coming Soon",IF(F32="","Active",IF(F32>TODAY(),"Leaving Soon","Removed"))) -> Active | E32: 45931 | G32: =MONTHDUR(E32,F32) -> 0.46666667 | H32: 41395 | I32: =YEARDUR(H32,E32) -> 12.416667 | J32: 80 | K32: 5 | L32: Action-Adventure | N32: Ubisoft games joining with price increase | R32: =IF(S32="","TBD",IF(S32>TODAY(),"Coming Soon",IF(F32="","Active",IF(F32>TODAY(),"Leaving Soon","Removed")))) -> TBD | T32: =MONTHDUR(E32,S32) -> 0.46666667
A33: Far Cry Primal | B33: Xbox / PC | C33: Yes | D33: =IF(E33>TODAY(),"Coming Soon",IF(F33="","Active",IF(F33>TODAY(),"Leaving Soon","Removed"))) -> Active | E33: 45931 | G33: =MONTHDUR(E33,F33) -> 0.46666667 | H33: 42423 | I33: =YEARDUR(H33,E33) -> 9.6055556 | J33: 76 | K33: 15 | L33: Action-Adventure | N33: Ubisoft games joining with price increase | R33: =IF(S33="","TBD",IF(S33>TODAY(),"Coming Soon",IF(F33="","Active",IF(F33>TODAY(),"Leaving Soon","Removed")))) -> TBD | T33: =MONTHDUR(E33,S33) -> 0.46666667
A34: Hungry Shark World | B34: Xbox / PC | C34: Yes | D34: =IF(E34>TODAY(),"Coming Soon",IF(F34="","Active",IF(F34>TODAY(),"Leaving Soon","Removed"))) -> Active | E34: 45931 | G34: =MONTHDUR(E34,F34) -> 0.46666667 | H34: 43298 | I34: =YEARDUR(H34,E34) -> 7.2055556 | J34: 58 | K34: 8 | L34: Action-Adventure | N34: Ubisoft games joining with price increase | R34: =IF(S34="","TBD",IF(S34>TODAY(),"Coming Soon",IF(F34="","Active",IF(F34>TODAY(),"Leaving Soon","Removed")))) -> TBD | T34: =MONTHDUR(E34,S34) -> 0.46666667
A35: Monopoly Madness | B35: Xbox / PC | C35: Yes | D35: =IF(E35>TODAY(),"Coming Soon",IF(F35="","Active",IF(F35>TODAY(),"Leaving Soon","Removed"))) -> Active | E35: 45931 | G35: =MONTHDUR(E35,F35) -> 0.46666667 | H35: 44914 | I35: =YEARDUR(H35,E35) -> 2.7833333 | K35: 6 | L35: Party | N35: Ubisoft games joining with price increase | R35: =IF(S35="","TBD",IF(S35>TODAY(),"Coming Soon",IF(F35="","Active",IF(F35>TODAY(),"Leaving Soon","Removed")))) -> TBD | T35: =MONTHDUR(E35,S35) -> 0.46666667
A36: Monopoly (2024) | B36: Xbox / PC | C36: Yes | D36: =IF(E36>TODAY(),"Coming Soon",IF(F36="","Active",IF(F36>TODAY(),"Leaving Soon","Removed"))) -> Active | E36: 45931 | G36: =MONTHDUR(E36,F36) -> 0.46666667 | H36: 45561 | I36: =YEARDUR(H36,E36) -> 1.0138889 | J36: 74 | K36: 14 | L36: Board | N36: Ubisoft games joining with price increase | R36: =IF(S36="","TBD",IF(S36>TODAY(),"Coming Soon",IF(F36="","Active",IF(F36>TODAY(),"Leaving Soon","Removed")))) -> TBD | T36: =MONTHDUR(E36,S36) -> 0.46666667
A37: OddBallers | B37: Xbox / PC | C37: Yes | D37: =IF(E37>TODAY(),"Coming Soon",IF(F37="","Active",IF(F37>TODAY(),"Leaving Soon","Removed"))) -> Active | E37: 45931 | G37: =MONTHDUR(E37,F37) -> 0.46666667 | H37: 44952 | I37: =YEARDUR(H37,E37) -> 2.6805556 | J37: 71 | K37: 8 | L37: Party | N37: Ubisoft games joining with price increase | R37: =IF(S37="","TBD",IF(S37>TODAY(),"Coming Soon",IF(F37="","Active",IF(F37>TODAY(),"Leaving Soon","Removed")))) -> TBD | T37: =MONTHDUR(E37,S37) -> 0.46666667
A38: Prince of Persia: The Lost Crown | B38: Xbox / PC | C38: Yes | D38: =IF(E38>TODAY(),"Coming Soon",IF(F38="","Active",IF(F38>TODAY(),"Leaving Soon","Removed"))) -> Active | E38: 45931 | G38: =MONTHDUR(E38,F38) -> 0.46666667 | H38: 45309 | I38: =YEARDUR(H38,E38) -> 1.7027778 | J38: 86 | K38: 17 | L38: Metroidvania | N38: Ubisoft games joining with price increase | R38: =IF(S38="","TBD",IF(S38>TODAY(),"Coming Soon",IF(F38="","Active",IF(F38>TODAY(),"Leaving Soon","Removed")))) -> TBD | T38: =MONTHDUR(E38,S38) -> 0.46666667
A39: Rabbids Invasion: The Interactive TV Show | B39: Xbox | C39: Yes | D39: =IF(E39>TODAY(),"Coming Soon",IF(F39="","Active",IF(F39>TODAY(),"Leaving Soon","Removed"))) -> Active | E39: 45931 | G39: =MONTHDUR(E39,F39) -> 0.46666667 | H39: 41951 | I39: =YEARDUR(H39,E39) -> 10.897222 | J39: 53 | K39: 10 | L39: Party | N39: Ubisoft games joining with price increase | R39: =IF(S39="","TBD",IF(S39>TODAY(),"Coming Soon",IF(F39="","Active",IF(F39>TODAY(),"Leaving Soon","Removed")))) -> TBD | T39: =MONTHDUR(E39,S39) -> 0.46666667
A40: Rabbids: Party of Legends | B40: Xbox / PC | C40: Yes | D40: =IF(E40>TODAY(),"Coming Soon",IF(F40="","Active",IF(F40>TODAY(),"Leaving Soon","Removed"))) -> Active | E40: 45931 | G40: =MONTHDUR(E40,F40) -> 0.46666667 | H40: 44742 | I40: =YEARDUR(H40,E40) -> 3.2527778 | J40: 69 | K40: 3 | L40: Party | N40: Ubisoft games joining with price increase | R40: =IF(S40="","TBD",IF(S40>TODAY(),"Coming Soon",IF(F40="","Active",IF(F40>TODAY(),"Leaving Soon","Removed")))) -> TBD | T40: =MONTHDUR(E40,S40) -> 0.46666667
...

Sheet Likely Leaving
A1: Complete Game Pass Master List by u/ABattleVet | B1: =COUNTIF(D2:D544,"Active")+COUNTIF(D2:D544,"Leaving Soon") -> 31 | C1: https://www.trueachievements.com/gamer/Bloomy/blog | Q1: l
A2: Game | B2: System | C2: xCloud | D2: Status | E2: Added | F2: Removed | G2: Months | H2: Release | I2: Age | J2: Metacritic | K2: Completion | L2: Genre (Giantbomb) | M2: Xbox Series X|S | N2: Owner Notes | O2: ESRB | P2: ESRB Content Descriptors | Q2: Public Notes
A3: =IFERROR(__xludf.DUMMYFUNCTION("SORT(FILTER('Master List'!A:Q, 'Master List'!D:D=""Active"", ISNA(MATCH('Master List'!A:A, 'Xbox Game Studios'!A:A, 0)), ISNA(MATCH('Master List'!A:A, 'EA Play'!A:A, 0)), map('Master List'!G:G, lambda(a, if(isnumber(a), (a > 1) * ((mod(a, 12) > 10.5) + (m"&"od(a, 12) < 1)), 0)))),7,1)"),"Aliens: Dark Descent") -> Aliens: Dark Descent | B3: =IFERROR(__xludf.DUMMYFUNCTION("""COMPUTED_VALUE"""),"Xbox / PC") -> Xbox / PC | C3: =IFERROR(__xludf.DUMMYFUNCTION("""COMPUTED_VALUE"""),"Yes") -> Yes | D3: =IFERROR(__xludf.DUMMYFUNCTION("""COMPUTED_VALUE"""),"Active") -> Active | E3: =IFERROR(__xludf.DUMMYFUNCTION("""COMPUTED_VALUE"""),45623.0) -> 45623 | G3: =IFERROR(__xludf.DUMMYFUNCTION("""COMPUTED_VALUE"""),10.6) -> 10.6 | H3: =IFERROR(__xludf.DUMMYFUNCTION("""COMPUTED_VALUE"""),45097.0) -> 45097 | I3: =IFERROR(__xludf.DUMMYFUNCTION("""COMPUTED_VALUE"""),1.4361111111111111) -> 1.4361111 | J3: =IFERROR(__xludf.DUMMYFUNCTION("""COMPUTED_VALUE"""),75.0) -> 75 | K3: =IFERROR(__xludf.DUMMYFUNCTION("""COMPUTED_VALUE"""),24.0) -> 24 | L3: =IFERROR(__xludf.DUMMYFUNCTION("""COMPUTED_VALUE"""),"Strategy") -> Strategy
A4: =IFERROR(__xludf.DUMMYFUNCTION("""COMPUTED_VALUE"""),"Nine Sols") -> Nine Sols | B4: =IFERROR(__xludf.DUMMYFUNCTION("""COMPUTED_VALUE"""),"Xbox / PC") -> Xbox / PC | C4: =IFERROR(__xludf.DUMMYFUNCTION("""COMPUTED_VALUE"""),"Yes") -> Yes | D4: =IFERROR(__xludf.DUMMYFUNCTION("""COMPUTED_VALUE"""),"Active") -> Active | E4: =IFERROR(__xludf.DUMMYFUNCTION("""COMPUTED_VALUE"""),45622.0) -> 45622 | G4: =IFERROR(__xludf.DUMMYFUNCTION("""COMPUTED_VALUE"""),10.633333333333333) -> 10.633333 | H4: =IFERROR(__xludf.DUMMYFUNCTION("""COMPUTED_VALUE"""),45440.0) -> 45440 | I4: =IFERROR(__xludf.DUMMYFUNCTION("""COMPUTED_VALUE"""),0.49444444444444446) -> 0.49444444 | J4: =IFERROR(__xludf.DUMMYFUNCTION("""COMPUTED_VALUE"""),83.0) -> 83 | K4: =IFERROR(__xludf.DUMMYFUNCTION("""COMPUTED_VALUE"""),21.0) -> 21 | L4: =IFERROR(__xludf.DUMMYFUNCTION("""COMPUTED_VALUE"""),"Platformer") -> Platformer | M4: =IFERROR(__xludf.DUMMYFUNCTION("""COMPUTED_VALUE"""),"Exclusive") -> Exclusive | N4: =IFERROR(__xludf.DUMMYFUNCTION("""COMPUTED_VALUE"""),"Joins GP in time for day one on console") -> Joins GP in time for day one on console
A5: =IFERROR(__xludf.DUMMYFUNCTION("""COMPUTED_VALUE"""),"S.T.A.L.K.E.R. 2: Heart of Chornobyl") -> S.T.A.L.K.E.R. 2: Heart of Chornobyl | B5: =IFERROR(__xludf.DUMMYFUNCTION("""COMPUTED_VALUE"""),"Xbox / PC") -> Xbox / PC | C5: =IFERROR(__xludf.DUMMYFUNCTION("""COMPUTED_VALUE"""),"Yes") -> Yes | D5: =IFERROR(__xludf.DUMMYFUNCTION("""COMPUTED_VALUE"""),"Active") -> Active | E5: =IFERROR(__xludf.DUMMYFUNCTION("""COMPUTED_VALUE"""),45616.0) -> 45616 | G5: =IFERROR(__xludf.DUMMYFUNCTION("""COMPUTED_VALUE"""),10.833333333333334) -> 10.833333 | H5: =IFERROR(__xludf.DUMMYFUNCTION("""COMPUTED_VALUE"""),45616.0) -> 45616 | I5: =IFERROR(__xludf.DUMMYFUNCTION("""COMPUTED_VALUE"""),0.0) -> 0 | J5: =IFERROR(__xludf.DUMMYFUNCTION("""COMPUTED_VALUE"""),73.0) -> 73 | K5: =IFERROR(__xludf.DUMMYFUNCTION("""COMPUTED_VALUE"""),31.0) -> 31 | L5: =IFERROR(__xludf.DUMMYFUNCTION("""COMPUTED_VALUE"""),"Action-Adventure") -> Action-Adventure | M5: =IFERROR(__xludf.DUMMYFUNCTION("""COMPUTED_VALUE"""),"Exclusive") -> Exclusive
A6: =IFERROR(__xludf.DUMMYFUNCTION("""COMPUTED_VALUE"""),"Goat Simulator: Remastered") -> Goat Simulator: Remastered | B6: =IFERROR(__xludf.DUMMYFUNCTION("""COMPUTED_VALUE"""),"Xbox / PC") -> Xbox / PC | C6: =IFERROR(__xludf.DUMMYFUNCTION("""COMPUTED_VALUE"""),"Yes") -> Yes | D6: =IFERROR(__xludf.DUMMYFUNCTION("""COMPUTED_VALUE"""),"Active") -> Active | E6: =IFERROR(__xludf.DUMMYFUNCTION("""COMPUTED_VALUE"""),45603.0) -> 45603 | G6: =IFERROR(__xludf.DUMMYFUNCTION("""COMPUTED_VALUE"""),11.266666666666666) -> 11.266667 | H6: =IFERROR(__xludf.DUMMYFUNCTION("""COMPUTED_VALUE"""),45603.0) -> 45603 | I6: =IFERROR(__xludf.DUMMYFUNCTION("""COMPUTED_VALUE"""),0.0) -> 0 | J6: =IFERROR(__xludf.DUMMYFUNCTION("""COMPUTED_VALUE"""),65.0) -> 65 | K6: =IFERROR(__xludf.DUMMYFUNCTION("""COMPUTED_VALUE"""),3.0) -> 3 | L6: =IFERROR(__xludf.DUMMYFUNCTION("""COMPUTED_VALUE"""),"Action-Adventure") -> Action-Adventure | M6: =IFERROR(__xludf.DUMMYFUNCTION("""COMPUTED_VALUE"""),"Exclusive") -> Exclusive
A7: =IFERROR(__xludf.DUMMYFUNCTION("""COMPUTED_VALUE"""),"Metal Slug: Tactics") -> Metal Slug: Tactics | B7: =IFERROR(__xludf.DUMMYFUNCTION("""COMPUTED_VALUE"""),"Xbox / PC") -> Xbox / PC | C7: =IFERROR(__xludf.DUMMYFUNCTION("""COMPUTED_VALUE"""),"Yes") -> Yes | D7: =IFERROR(__xludf.DUMMYFUNCTION("""COMPUTED_VALUE"""),"Active") -> Active | E7: =IFERROR(__xludf.DUMMYFUNCTION("""COMPUTED_VALUE"""),45601.0) -> 45601 | G7: =IFERROR(__xludf.DUMMYFUNCTION("""COMPUTED_VALUE"""),11.333333333333332) -> 11.333333 | H7: =IFERROR(__xludf.DUMMYFUNCTION("""COMPUTED_VALUE"""),45601.0) -> 45601 | I7: =IFERROR(__xludf.DUMMYFUNCTION("""COMPUTED_VALUE"""),0.0) -> 0 | J7: =IFERROR(__xludf.DUMMYFUNCTION("""COMPUTED_VALUE"""),79.0) -> 79 | K7: =IFERROR(__xludf.DUMMYFUNCTION("""COMPUTED_VALUE"""),8.0) -> 8 | L7: =IFERROR(__xludf.DUMMYFUNCTION("""COMPUTED_VALUE"""),"Strategy") -> Strategy
A8: =IFERROR(__xludf.DUMMYFUNCTION("""COMPUTED_VALUE"""),"Ashen") -> Ashen | B8: =IFERROR(__xludf.DUMMYFUNCTION("""COMPUTED_VALUE"""),"Xbox / PC") -> Xbox / PC | D8: =IFERROR(__xludf.DUMMYFUNCTION("""COMPUTED_VALUE"""),"Active") -> Active | E8: =IFERROR(__xludf.DUMMYFUNCTION("""COMPUTED_VALUE"""),45594.0) -> 45594 | G8: =IFERROR(__xludf.DUMMYFUNCTION("""COMPUTED_VALUE"""),11.533333333333333) -> 11.533333 | H8: =IFERROR(__xludf.DUMMYFUNCTION("""COMPUTED_VALUE"""),43441.0) -> 43441 | I8: =IFERROR(__xludf.DUMMYFUNCTION("""COMPUTED_VALUE"""),5.894444444444445) -> 5.8944444 | J8: =IFERROR(__xludf.DUMMYFUNCTION("""COMPUTED_VALUE"""),78.0) -> 78 | K8: =IFERROR(__xludf.DUMMYFUNCTION("""COMPUTED_VALUE"""),15.5) -> 15.5 | L8: =IFERROR(__xludf.DUMMYFUNCTION("""COMPUTED_VALUE"""),"Action / RPG / Action-Adventure") -> Action / RPG / Action-Adventure | N8: =IFERROR(__xludf.DUMMYFUNCTION("""COMPUTED_VALUE"""),"Returning title: Originally joined 12/31/18, left 12/1/19") -> Returning title: Originally joined 12/31/18, left 12/1/19
A9: =IFERROR(__xludf.DUMMYFUNCTION("""COMPUTED_VALUE"""),"Call of Duty: Warzone") -> Call of Duty: Warzone | B9: =IFERROR(__xludf.DUMMYFUNCTION("""COMPUTED_VALUE"""),"Xbox / PC") -> Xbox / PC | C9: =IFERROR(__xludf.DUMMYFUNCTION("""COMPUTED_VALUE"""),"Yes") -> Yes | D9: =IFERROR(__xludf.DUMMYFUNCTION("""COMPUTED_VALUE"""),"Active") -> Active | E9: =IFERROR(__xludf.DUMMYFUNCTION("""COMPUTED_VALUE"""),45590.0) -> 45590 | G9: =IFERROR(__xludf.DUMMYFUNCTION("""COMPUTED_VALUE"""),11.666666666666666) -> 11.666667 | H9: =IFERROR(__xludf.DUMMYFUNCTION("""COMPUTED_VALUE"""),44881.0) -> 44881 | I9: =IFERROR(__xludf.DUMMYFUNCTION("""COMPUTED_VALUE"""),1.9416666666666667) -> 1.9416667 | J9: =IFERROR(__xludf.DUMMYFUNCTION("""COMPUTED_VALUE"""),79.0) -> 79 | K9: =IFERROR(__xludf.DUMMYFUNCTION("""COMPUTED_VALUE"""),99.0) -> 99 | L9: =IFERROR(__xludf.DUMMYFUNCTION("""COMPUTED_VALUE"""),"Shooter") -> Shooter | N9: =IFERROR(__xludf.DUMMYFUNCTION("""COMPUTED_VALUE"""),"Joins cloud on 10/25/24 (GPU only), free to play") -> Joins cloud on 10/25/24 (GPU only), free to play
A10: =IFERROR(__xludf.DUMMYFUNCTION("""COMPUTED_VALUE"""),"Donut County") -> Donut County | B10: =IFERROR(__xludf.DUMMYFUNCTION("""COMPUTED_VALUE"""),"Xbox / PC") -> Xbox / PC | C10: =IFERROR(__xludf.DUMMYFUNCTION("""COMPUTED_VALUE"""),"Touch Controls") -> Touch Controls | D10: =IFERROR(__xludf.DUMMYFUNCTION("""COMPUTED_VALUE"""),"Active") -> Active | E10: =IFERROR(__xludf.DUMMYFUNCTION("""COMPUTED_VALUE"""),45582.0) -> 45582 | G10: =IFERROR(__xludf.DUMMYFUNCTION("""COMPUTED_VALUE"""),11.933333333333334) -> 11.933333 | H10: =IFERROR(__xludf.DUMMYFUNCTION("""COMPUTED_VALUE"""),43340.0) -> 43340 | I10: =IFERROR(__xludf.DUMMYFUNCTION("""COMPUTED_VALUE"""),6.136111111111111) -> 6.1361111 | J10: =IFERROR(__xludf.DUMMYFUNCTION("""COMPUTED_VALUE"""),82.0) -> 82 | K10: =IFERROR(__xludf.DUMMYFUNCTION("""COMPUTED_VALUE"""),2.0) -> 2 | L10: =IFERROR(__xludf.DUMMYFUNCTION("""COMPUTED_VALUE"""),"Action") -> Action | N10: =IFERROR(__xludf.DUMMYFUNCTION("""COMPUTED_VALUE"""),"Returning title: Originally joined 1/21/21, left 1/31/23, Official PC Mod Support") -> Returning title: Originally joined 1/21/21, left 1/31/23, Official PC Mod Support | O10: =IFERROR(__xludf.DUMMYFUNCTION("""COMPUTED_VALUE"""),"E") -> E | P10: =IFERROR(__xludf.DUMMYFUNCTION("""COMPUTED_VALUE"""),"Mild Fantasy Violence, Comic Mischief") -> Mild Fantasy Violence, Comic Mischief
A11: =IFERROR(__xludf.DUMMYFUNCTION("""COMPUTED_VALUE"""),"Mechwarrior 5: Clans") -> Mechwarrior 5: Clans | B11: =IFERROR(__xludf.DUMMYFUNCTION("""COMPUTED_VALUE"""),"Xbox / PC") -> Xbox / PC | C11: =IFERROR(__xludf.DUMMYFUNCTION("""COMPUTED_VALUE"""),"Yes") -> Yes | D11: =IFERROR(__xludf.DUMMYFUNCTION("""COMPUTED_VALUE"""),"Active") -> Active | E11: =IFERROR(__xludf.DUMMYFUNCTION("""COMPUTED_VALUE"""),45582.0) -> 45582 | G11: =IFERROR(__xludf.DUMMYFUNCTION("""COMPUTED_VALUE"""),11.933333333333334) -> 11.933333 | H11: =IFERROR(__xludf.DUMMYFUNCTION("""COMPUTED_VALUE"""),45582.0) -> 45582 | I11: =IFERROR(__xludf.DUMMYFUNCTION("""COMPUTED_VALUE"""),0.0) -> 0 | J11: =IFERROR(__xludf.DUMMYFUNCTION("""COMPUTED_VALUE"""),79.0) -> 79 | K11: =IFERROR(__xludf.DUMMYFUNCTION("""COMPUTED_VALUE"""),23.0) -> 23 | L11: =IFERROR(__xludf.DUMMYFUNCTION("""COMPUTED_VALUE"""),"Simulation") -> Simulation | M11: =IFERROR(__xludf.DUMMYFUNCTION("""COMPUTED_VALUE"""),"Exclusive") -> Exclusive
A12: =IFERROR(__xludf.DUMMYFUNCTION("""COMPUTED_VALUE"""),"South Park: The Fractured but Whole") -> South Park: The Fractured but Whole | B12: =IFERROR(__xludf.DUMMYFUNCTION("""COMPUTED_VALUE"""),"Xbox / PC") -> Xbox / PC | C12: =IFERROR(__xludf.DUMMYFUNCTION("""COMPUTED_VALUE"""),"Yes") -> Yes | D12: =IFERROR(__xludf.DUMMYFUNCTION("""COMPUTED_VALUE"""),"Active") -> Active | E12: =IFERROR(__xludf.DUMMYFUNCTION("""COMPUTED_VALUE"""),45581.0) -> 45581 | G12: =IFERROR(__xludf.DUMMYFUNCTION("""COMPUTED_VALUE"""),11.966666666666667) -> 11.966667 | H12: =IFERROR(__xludf.DUMMYFUNCTION("""COMPUTED_VALUE"""),43312.0) -> 43312 | I12: =IFERROR(__xludf.DUMMYFUNCTION("""COMPUTED_VALUE"""),6.211111111111111) -> 6.2111111 | J12: =IFERROR(__xludf.DUMMYFUNCTION("""COMPUTED_VALUE"""),75.0) -> 75 | K12: =IFERROR(__xludf.DUMMYFUNCTION("""COMPUTED_VALUE"""),18.0) -> 18 | L12: =IFERROR(__xludf.DUMMYFUNCTION("""COMPUTED_VALUE"""),"RPG") -> RPG
A13: =IFERROR(__xludf.DUMMYFUNCTION("""COMPUTED_VALUE"""),"Inscryption") -> Inscryption | B13: =IFERROR(__xludf.DUMMYFUNCTION("""COMPUTED_VALUE"""),"Xbox / PC") -> Xbox / PC | C13: =IFERROR(__xludf.DUMMYFUNCTION("""COMPUTED_VALUE"""),"Yes") -> Yes | D13: =IFERROR(__xludf.DUMMYFUNCTION("""COMPUTED_VALUE"""),"Active") -> Active | E13: =IFERROR(__xludf.DUMMYFUNCTION("""COMPUTED_VALUE"""),45575.0) -> 45575 | G13: =IFERROR(__xludf.DUMMYFUNCTION("""COMPUTED_VALUE"""),12.166666666666666) -> 12.166667 | H13: =IFERROR(__xludf.DUMMYFUNCTION("""COMPUTED_VALUE"""),44488.0) -> 44488 | I13: =IFERROR(__xludf.DUMMYFUNCTION("""COMPUTED_VALUE"""),2.975) -> 2.975 | J13: =IFERROR(__xludf.DUMMYFUNCTION("""COMPUTED_VALUE"""),85.0) -> 85 | K13: =IFERROR(__xludf.DUMMYFUNCTION("""COMPUTED_VALUE"""),13.0) -> 13 | L13: =IFERROR(__xludf.DUMMYFUNCTION("""COMPUTED_VALUE"""),"Card Battle") -> Card Battle
A14: =IFERROR(__xludf.DUMMYFUNCTION("""COMPUTED_VALUE"""),"Mad Streets") -> Mad Streets | B14: =IFERROR(__xludf.DUMMYFUNCTION("""COMPUTED_VALUE"""),"Xbox / PC") -> Xbox / PC | C14: =IFERROR(__xludf.DUMMYFUNCTION("""COMPUTED_VALUE"""),"Yes") -> Yes | D14: =IFERROR(__xludf.DUMMYFUNCTION("""COMPUTED_VALUE"""),"Active") -> Active | E14: =IFERROR(__xludf.DUMMYFUNCTION("""COMPUTED_VALUE"""),45572.0) -> 45572 | G14: =IFERROR(__xludf.DUMMYFUNCTION("""COMPUTED_VALUE"""),12.266666666666666) -> 12.266667 | H14: =IFERROR(__xludf.DUMMYFUNCTION("""COMPUTED_VALUE"""),44435.0) -> 44435 | I14: =IFERROR(__xludf.DUMMYFUNCTION("""COMPUTED_VALUE"""),3.111111111111111) -> 3.1111111 | J14: =IFERROR(__xludf.DUMMYFUNCTION("""COMPUTED_VALUE"""),55.0) -> 55 | K14: =IFERROR(__xludf.DUMMYFUNCTION("""COMPUTED_VALUE"""),2.0) -> 2 | L14: =IFERROR(__xludf.DUMMYFUNCTION("""COMPUTED_VALUE"""),"Beat-'Em-Up ") -> Beat-'Em-Up
A15: =IFERROR(__xludf.DUMMYFUNCTION("""COMPUTED_VALUE"""),"SIFU") -> SIFU | B15: =IFERROR(__xludf.DUMMYFUNCTION("""COMPUTED_VALUE"""),"Xbox / PC") -> Xbox / PC | C15: =IFERROR(__xludf.DUMMYFUNCTION("""COMPUTED_VALUE"""),"Yes") -> Yes | D15: =IFERROR(__xludf.DUMMYFUNCTION("""COMPUTED_VALUE"""),"Active") -> Active | E15: =IFERROR(__xludf.DUMMYFUNCTION("""COMPUTED_VALUE"""),45567.0) -> 45567 | G15: =IFERROR(__xludf.DUMMYFUNCTION("""COMPUTED_VALUE"""),12.433333333333334) -> 12.433333 | H15: =IFERROR(__xludf.DUMMYFUNCTION("""COMPUTED_VALUE"""),44600.0) -> 44600 | I15: =IFERROR(__xludf.DUMMYFUNCTION("""COMPUTED_VALUE"""),2.65) -> 2.65 | J15: =IFERROR(__xludf.DUMMYFUNCTION("""COMPUTED_VALUE"""),81.0) -> 81 | K15: =IFERROR(__xludf.DUMMYFUNCTION("""COMPUTED_VALUE"""),9.0) -> 9 | L15: =IFERROR(__xludf.DUMMYFUNCTION("""COMPUTED_VALUE"""),"Xbox / PC") -> Xbox / PC
A16: =IFERROR(__xludf.DUMMYFUNCTION("""COMPUTED_VALUE"""),"Legend of Mana (2021)") -> Legend of Mana (2021) | B16: =IFERROR(__xludf.DUMMYFUNCTION("""COMPUTED_VALUE"""),"Xbox / PC") -> Xbox / PC | C16: =IFERROR(__xludf.DUMMYFUNCTION("""COMPUTED_VALUE"""),"Yes") -> Yes | D16: =IFERROR(__xludf.DUMMYFUNCTION("""COMPUTED_VALUE"""),"Active") -> Active | E16: =IFERROR(__xludf.DUMMYFUNCTION("""COMPUTED_VALUE"""),45561.0) -> 45561 | G16: =IFERROR(__xludf.DUMMYFUNCTION("""COMPUTED_VALUE"""),12.633333333333333) -> 12.633333 | H16: =IFERROR(__xludf.DUMMYFUNCTION("""COMPUTED_VALUE"""),44371.0) -> 44371 | I16: =IFERROR(__xludf.DUMMYFUNCTION("""COMPUTED_VALUE"""),3.2555555555555555) -> 3.2555556 | J16: =IFERROR(__xludf.DUMMYFUNCTION("""COMPUTED_VALUE"""),72.0) -> 72 | K16: =IFERROR(__xludf.DUMMYFUNCTION("""COMPUTED_VALUE"""),18.0) -> 18 | L16: =IFERROR(__xludf.DUMMYFUNCTION("""COMPUTED_VALUE"""),"RPG") -> RPG
A17: =IFERROR(__xludf.DUMMYFUNCTION("""COMPUTED_VALUE"""),"Trials of Mana (2020)") -> Trials of Mana (2020) | B17: =IFERROR(__xludf.DUMMYFUNCTION("""COMPUTED_VALUE"""),"Xbox / PC") -> Xbox / PC | C17: =IFERROR(__xludf.DUMMYFUNCTION("""COMPUTED_VALUE"""),"Yes") -> Yes | D17: =IFERROR(__xludf.DUMMYFUNCTION("""COMPUTED_VALUE"""),"Active") -> Active | E17: =IFERROR(__xludf.DUMMYFUNCTION("""COMPUTED_VALUE"""),45561.0) -> 45561 | G17: =IFERROR(__xludf.DUMMYFUNCTION("""COMPUTED_VALUE"""),12.633333333333333) -> 12.633333 | H17: =IFERROR(__xludf.DUMMYFUNCTION("""COMPUTED_VALUE"""),43945.0) -> 43945 | I17: =IFERROR(__xludf.DUMMYFUNCTION("""COMPUTED_VALUE"""),4.4222222222222225) -> 4.4222222 | J17: =IFERROR(__xludf.DUMMYFUNCTION("""COMPUTED_VALUE"""),76.0) -> 76 | K17: =IFERROR(__xludf.DUMMYFUNCTION("""COMPUTED_VALUE"""),21.0) -> 21 | L17: =IFERROR(__xludf.DUMMYFUNCTION("""COMPUTED_VALUE"""),"RPG") -> RPG
A18: =IFERROR(__xludf.DUMMYFUNCTION("""COMPUTED_VALUE"""),"Ara: History Untold") -> Ara: History Untold | B18: =IFERROR(__xludf.DUMMYFUNCTION("""COMPUTED_VALUE"""),"PC") -> PC | D18: =IFERROR(__xludf.DUMMYFUNCTION("""COMPUTED_VALUE"""),"Active") -> Active | E18: =IFERROR(__xludf.DUMMYFUNCTION("""COMPUTED_VALUE"""),45559.0) -> 45559 | G18: =IFERROR(__xludf.DUMMYFUNCTION("""COMPUTED_VALUE"""),12.7) -> 12.7 | H18: =IFERROR(__xludf.DUMMYFUNCTION("""COMPUTED_VALUE"""),45559.0) -> 45559 | I18: =IFERROR(__xludf.DUMMYFUNCTION("""COMPUTED_VALUE"""),0.0) -> 0 | J18: =IFERROR(__xludf.DUMMYFUNCTION("""COMPUTED_VALUE"""),76.0) -> 76 | K18: =IFERROR(__xludf.DUMMYFUNCTION("""COMPUTED_VALUE"""),13.0) -> 13 | L18: =IFERROR(__xludf.DUMMYFUNCTION("""COMPUTED_VALUE"""),"Strategy") -> Strategy
A19: =IFERROR(__xludf.DUMMYFUNCTION("""COMPUTED_VALUE"""),"Frostpunk 2") -> Frostpunk 2 | B19: =IFERROR(__xludf.DUMMYFUNCTION("""COMPUTED_VALUE"""),"Xbox / PC") -> Xbox / PC | C19: =IFERROR(__xludf.DUMMYFUNCTION("""COMPUTED_VALUE"""),"Yes") -> Yes | D19: =IFERROR(__xludf.DUMMYFUNCTION("""COMPUTED_VALUE"""),"Active") -> Active | E19: =IFERROR(__xludf.DUMMYFUNCTION("""COMPUTED_VALUE"""),45555.0) -> 45555 | G19: =IFERROR(__xludf.DUMMYFUNCTION("""COMPUTED_VALUE"""),12.833333333333332) -> 12.833333 | H19: =IFERROR(__xludf.DUMMYFUNCTION("""COMPUTED_VALUE"""),45555.0) -> 45555 | I19: =IFERROR(__xludf.DUMMYFUNCTION("""COMPUTED_VALUE"""),0.0) -> 0 | J19: =IFERROR(__xludf.DUMMYFUNCTION("""COMPUTED_VALUE"""),86.0) -> 86 | K19: =IFERROR(__xludf.DUMMYFUNCTION("""COMPUTED_VALUE"""),11.0) -> 11 | L19: =IFERROR(__xludf.DUMMYFUNCTION("""COMPUTED_VALUE"""),"Simulation") -> Simulation | M19: =IFERROR(__xludf.DUMMYFUNCTION("""COMPUTED_VALUE"""),"Exclusive") -> Exclusive | N19: =IFERROR(__xludf.DUMMYFUNCTION("""COMPUTED_VALUE"""),"Joins console and cloud 9/18/25") -> Joins console and cloud 9/18/25
A20: =IFERROR(__xludf.DUMMYFUNCTION("""COMPUTED_VALUE"""),"Train Sim World 5") -> Train Sim World 5 | B20: =IFERROR(__xludf.DUMMYFUNCTION("""COMPUTED_VALUE"""),"Xbox / PC") -> Xbox / PC | C20: =IFERROR(__xludf.DUMMYFUNCTION("""COMPUTED_VALUE"""),"Yes") -> Yes | D20: =IFERROR(__xludf.DUMMYFUNCTION("""COMPUTED_VALUE"""),"Active") -> Active | E20: =IFERROR(__xludf.DUMMYFUNCTION("""COMPUTED_VALUE"""),45552.0) -> 45552 | G20: =IFERROR(__xludf.DUMMYFUNCTION("""COMPUTED_VALUE"""),12.933333333333334) -> 12.933333 | H20: =IFERROR(__xludf.DUMMYFUNCTION("""COMPUTED_VALUE"""),45195.0) -> 45195 | I20: =IFERROR(__xludf.DUMMYFUNCTION("""COMPUTED_VALUE"""),0.975) -> 0.975 | J20: =IFERROR(__xludf.DUMMYFUNCTION("""COMPUTED_VALUE"""),77.0) -> 77 | L20: =IFERROR(__xludf.DUMMYFUNCTION("""COMPUTED_VALUE"""),"Simulation") -> Simulation
A21: =IFERROR(__xludf.DUMMYFUNCTION("""COMPUTED_VALUE"""),"Spirittea") -> Spirittea | B21: =IFERROR(__xludf.DUMMYFUNCTION("""COMPUTED_VALUE"""),"Xbox / PC") -> Xbox / PC | C21: =IFERROR(__xludf.DUMMYFUNCTION("""COMPUTED_VALUE"""),"Yes") -> Yes | D21: =IFERROR(__xludf.DUMMYFUNCTION("""COMPUTED_VALUE"""),"Active") -> Active | E21: =IFERROR(__xludf.DUMMYFUNCTION("""COMPUTED_VALUE"""),45243.0) -> 45243 | G21: =IFERROR(__xludf.DUMMYFUNCTION("""COMPUTED_VALUE"""),23.066666666666666) -> 23.066667 | H21: =IFERROR(__xludf.DUMMYFUNCTION("""COMPUTED_VALUE"""),45243.0) -> 45243 | I21: =IFERROR(__xludf.DUMMYFUNCTION("""COMPUTED_VALUE"""),0.0) -> 0 | J21: =IFERROR(__xludf.DUMMYFUNCTION("""COMPUTED_VALUE"""),76.0) -> 76 | K21: =IFERROR(__xludf.DUMMYFUNCTION("""COMPUTED_VALUE"""),33.0) -> 33 | L21: =IFERROR(__xludf.DUMMYFUNCTION("""COMPUTED_VALUE"""),"Strategy / Adventure / RPG / Simulation") -> Strategy / Adventure / RPG / Simulation
A22: =IFERROR(__xludf.DUMMYFUNCTION("""COMPUTED_VALUE"""),"Football Manager 2024") -> Football Manager 2024 | B22: =IFERROR(__xludf.DUMMYFUNCTION("""COMPUTED_VALUE"""),"Xbox / PC") -> Xbox / PC | C22: =IFERROR(__xludf.DUMMYFUNCTION("""COMPUTED_VALUE"""),"Yes") -> Yes | D22: =IFERROR(__xludf.DUMMYFUNCTION("""COMPUTED_VALUE"""),"Active") -> Active | E22: =IFERROR(__xludf.DUMMYFUNCTION("""COMPUTED_VALUE"""),45236.0) -> 45236 | G22: =IFERROR(__xludf.DUMMYFUNCTION("""COMPUTED_VALUE"""),23.3) -> 23.3 | H22: =IFERROR(__xludf.DUMMYFUNCTION("""COMPUTED_VALUE"""),45236.0) -> 45236 | I22: =IFERROR(__xludf.DUMMYFUNCTION("""COMPUTED_VALUE"""),0.0) -> 0 | J22: =IFERROR(__xludf.DUMMYFUNCTION("""COMPUTED_VALUE"""),84.0) -> 84 | K22: =IFERROR(__xludf.DUMMYFUNCTION("""COMPUTED_VALUE"""),11.0) -> 11 | L22: =IFERROR(__xludf.DUMMYFUNCTION("""COMPUTED_VALUE"""),"Simulation / Soccer") -> Simulation / Soccer
A23: =IFERROR(__xludf.DUMMYFUNCTION("""COMPUTED_VALUE"""),"Thirsty Suitors") -> Thirsty Suitors | B23: =IFERROR(__xludf.DUMMYFUNCTION("""COMPUTED_VALUE"""),"Xbox / PC") -> Xbox / PC | C23: =IFERROR(__xludf.DUMMYFUNCTION("""COMPUTED_VALUE"""),"Yes") -> Yes | D23: =IFERROR(__xludf.DUMMYFUNCTION("""COMPUTED_VALUE"""),"Active") -> Active | E23: =IFERROR(__xludf.DUMMYFUNCTION("""COMPUTED_VALUE"""),45232.0) -> 45232 | G23: =IFERROR(__xludf.DUMMYFUNCTION("""COMPUTED_VALUE"""),23.433333333333334) -> 23.433333 | H23: =IFERROR(__xludf.DUMMYFUNCTION("""COMPUTED_VALUE"""),45232.0) -> 45232 | I23: =IFERROR(__xludf.DUMMYFUNCTION("""COMPUTED_VALUE"""),0.0) -> 0 | J23: =IFERROR(__xludf.DUMMYFUNCTION("""COMPUTED_VALUE"""),80.0) -> 80 | K23: =IFERROR(__xludf.DUMMYFUNCTION("""COMPUTED_VALUE"""),8.0) -> 8 | L23: =IFERROR(__xludf.DUMMYFUNCTION("""COMPUTED_VALUE"""),"Adventure / RPG") -> Adventure / RPG | O23: =IFERROR(__xludf.DUMMYFUNCTION("""COMPUTED_VALUE"""),"T") -> T
A24: =IFERROR(__xludf.DUMMYFUNCTION("""COMPUTED_VALUE"""),"Jusant") -> Jusant | B24: =IFERROR(__xludf.DUMMYFUNCTION("""COMPUTED_VALUE"""),"Xbox / PC") -> Xbox / PC | C24: =IFERROR(__xludf.DUMMYFUNCTION("""COMPUTED_VALUE"""),"Yes") -> Yes | D24: =IFERROR(__xludf.DUMMYFUNCTION("""COMPUTED_VALUE"""),"Active") -> Active | E24: =IFERROR(__xludf.DUMMYFUNCTION("""COMPUTED_VALUE"""),45230.0) -> 45230 | G24: =IFERROR(__xludf.DUMMYFUNCTION("""COMPUTED_VALUE"""),23.5) -> 23.5 | H24: =IFERROR(__xludf.DUMMYFUNCTION("""COMPUTED_VALUE"""),45230.0) -> 45230 | I24: =IFERROR(__xludf.DUMMYFUNCTION("""COMPUTED_VALUE"""),0.0) -> 0 | J24: =IFERROR(__xludf.DUMMYFUNCTION("""COMPUTED_VALUE"""),83.0) -> 83 | K24: =IFERROR(__xludf.DUMMYFUNCTION("""COMPUTED_VALUE"""),4.0) -> 4 | L24: =IFERROR(__xludf.DUMMYFUNCTION("""COMPUTED_VALUE"""),"Adventure") -> Adventure | O24: =IFERROR(__xludf.DUMMYFUNCTION("""COMPUTED_VALUE"""),"RP") -> RP
A25: =IFERROR(__xludf.DUMMYFUNCTION("""COMPUTED_VALUE"""),"Wartales") -> Wartales | B25: =IFERROR(__xludf.DUMMYFUNCTION("""COMPUTED_VALUE"""),"Xbox / PC") -> Xbox / PC | C25: =IFERROR(__xludf.DUMMYFUNCTION("""COMPUTED_VALUE"""),"Yes") -> Yes | D25: =IFERROR(__xludf.DUMMYFUNCTION("""COMPUTED_VALUE"""),"Active") -> Active | E25: =IFERROR(__xludf.DUMMYFUNCTION("""COMPUTED_VALUE"""),45230.0) -> 45230 | G25: =IFERROR(__xludf.DUMMYFUNCTION("""COMPUTED_VALUE"""),23.5) -> 23.5 | H25: =IFERROR(__xludf.DUMMYFUNCTION("""COMPUTED_VALUE"""),44531.0) -> 44531 | I25: =IFERROR(__xludf.DUMMYFUNCTION("""COMPUTED_VALUE"""),1.913888888888889) -> 1.9138889 | J25: =IFERROR(__xludf.DUMMYFUNCTION("""COMPUTED_VALUE"""),80.0) -> 80 | K25: =IFERROR(__xludf.DUMMYFUNCTION("""COMPUTED_VALUE"""),38.0) -> 38 | L25: =IFERROR(__xludf.DUMMYFUNCTION("""COMPUTED_VALUE"""),"Strategy / Adventure / RPG") -> Strategy / Adventure / RPG | N25: =IFERROR(__xludf.DUMMYFUNCTION("""COMPUTED_VALUE"""),"Joined xbox one ine June 2024") -> Joined xbox one ine June 2024
A26: =IFERROR(__xludf.DUMMYFUNCTION("""COMPUTED_VALUE"""),"Cities: Skylines II") -> Cities: Skylines II | B26: =IFERROR(__xludf.DUMMYFUNCTION("""COMPUTED_VALUE"""),"PC") -> PC | D26: =IFERROR(__xludf.DUMMYFUNCTION("""COMPUTED_VALUE"""),"Active") -> Active | E26: =IFERROR(__xludf.DUMMYFUNCTION("""COMPUTED_VALUE"""),45223.0) -> 45223 | G26: =IFERROR(__xludf.DUMMYFUNCTION("""COMPUTED_VALUE"""),23.700000000000003) -> 23.7 | H26: =IFERROR(__xludf.DUMMYFUNCTION("""COMPUTED_VALUE"""),45223.0) -> 45223 | I26: =IFERROR(__xludf.DUMMYFUNCTION("""COMPUTED_VALUE"""),0.0) -> 0 | J26: =IFERROR(__xludf.DUMMYFUNCTION("""COMPUTED_VALUE"""),75.0) -> 75 | K26: =IFERROR(__xludf.DUMMYFUNCTION("""COMPUTED_VALUE"""),25.0) -> 25 | L26: =IFERROR(__xludf.DUMMYFUNCTION("""COMPUTED_VALUE"""),"Simulation") -> Simulation | O26: =IFERROR(__xludf.DUMMYFUNCTION("""COMPUTED_VALUE"""),"RP") -> RP
A27: =IFERROR(__xludf.DUMMYFUNCTION("""COMPUTED_VALUE"""),"Return to Monkey Island") -> Return to Monkey Island | B27: =IFERROR(__xludf.DUMMYFUNCTION("""COMPUTED_VALUE"""),"Xbox / PC") -> Xbox / PC | C27: =IFERROR(__xludf.DUMMYFUNCTION("""COMPUTED_VALUE"""),"Yes") -> Yes | D27: =IFERROR(__xludf.DUMMYFUNCTION("""COMPUTED_VALUE"""),"Active") -> Active | E27: =IFERROR(__xludf.DUMMYFUNCTION("""COMPUTED_VALUE"""),44873.0) -> 44873 | G27: =IFERROR(__xludf.DUMMYFUNCTION("""COMPUTED_VALUE"""),35.233333333333334) -> 35.233333 | H27: =IFERROR(__xludf.DUMMYFUNCTION("""COMPUTED_VALUE"""),44823.0) -> 44823 | I27: =IFERROR(__xludf.DUMMYFUNCTION("""COMPUTED_VALUE"""),0.1361111111111111) -> 0.13611111 | J27: =IFERROR(__xludf.DUMMYFUNCTION("""COMPUTED_VALUE"""),87.0) -> 87 | K27: =IFERROR(__xludf.DUMMYFUNCTION("""COMPUTED_VALUE"""),10.5) -> 10.5 | L27: =IFERROR(__xludf.DUMMYFUNCTION("""COMPUTED_VALUE"""),"Adventure") -> Adventure | M27: =IFERROR(__xludf.DUMMYFUNCTION("""COMPUTED_VALUE"""),"Exclusive") -> Exclusive | O27: =IFERROR(__xludf.DUMMYFUNCTION("""COMPUTED_VALUE"""),"E10+") -> E10+ | P27: =IFERROR(__xludf.DUMMYFUNCTION("""COMPUTED_VALUE"""),"Alcohol Reference, Fantasy Violence") -> Alcohol Reference, Fantasy Violence
A28: =IFERROR(__xludf.DUMMYFUNCTION("""COMPUTED_VALUE"""),"A Plague Tale: Requiem") -> A Plague Tale: Requiem | B28: =IFERROR(__xludf.DUMMYFUNCTION("""COMPUTED_VALUE"""),"Xbox / PC") -> Xbox / PC | C28: =IFERROR(__xludf.DUMMYFUNCTION("""COMPUTED_VALUE"""),"Yes") -> Yes | D28: =IFERROR(__xludf.DUMMYFUNCTION("""COMPUTED_VALUE"""),"Active") -> Active | E28: =IFERROR(__xludf.DUMMYFUNCTION("""COMPUTED_VALUE"""),44852.0) -> 44852 | G28: =IFERROR(__xludf.DUMMYFUNCTION("""COMPUTED_VALUE"""),35.9) -> 35.9 | H28: =IFERROR(__xludf.DUMMYFUNCTION("""COMPUTED_VALUE"""),44852.0) -> 44852 | I28: =IFERROR(__xludf.DUMMYFUNCTION("""COMPUTED_VALUE"""),0.0) -> 0 | J28: =IFERROR(__xludf.DUMMYFUNCTION("""COMPUTED_VALUE"""),85.0) -> 85 | K28: =IFERROR(__xludf.DUMMYFUNCTION("""COMPUTED_VALUE"""),15.0) -> 15 | L28: =IFERROR(__xludf.DUMMYFUNCTION("""COMPUTED_VALUE"""),"Action-Adventure") -> Action-Adventure | M28: =IFERROR(__xludf.DUMMYFUNCTION("""COMPUTED_VALUE"""),"Exclusive") -> Exclusive | O28: =IFERROR(__xludf.DUMMYFUNCTION("""COMPUTED_VALUE"""),"M") -> M | P28: =IFERROR(__xludf.DUMMYFUNCTION("""COMPUTED_VALUE"""),"Intense Violence, Blood, Language") -> Intense Violence, Blood, Language
A29: =IFERROR(__xludf.DUMMYFUNCTION("""COMPUTED_VALUE"""),"Chivalry II") -> Chivalry II | B29: =IFERROR(__xludf.DUMMYFUNCTION("""COMPUTED_VALUE"""),"Xbox / PC") -> Xbox / PC | C29: =IFERROR(__xludf.DUMMYFUNCTION("""COMPUTED_VALUE"""),"Yes") -> Yes | D29: =IFERROR(__xludf.DUMMYFUNCTION("""COMPUTED_VALUE"""),"Active") -> Active | E29: =IFERROR(__xludf.DUMMYFUNCTION("""COMPUTED_VALUE"""),44838.0) -> 44838 | G29: =IFERROR(__xludf.DUMMYFUNCTION("""COMPUTED_VALUE"""),36.36666666666667) -> 36.366667 | H29: =IFERROR(__xludf.DUMMYFUNCTION("""COMPUTED_VALUE"""),44355.0) -> 44355 | I29: =IFERROR(__xludf.DUMMYFUNCTION("""COMPUTED_VALUE"""),1.3222222222222222) -> 1.3222222 | J29: =IFERROR(__xludf.DUMMYFUNCTION("""COMPUTED_VALUE"""),82.0) -> 82 | K29: =IFERROR(__xludf.DUMMYFUNCTION("""COMPUTED_VALUE"""),42.5) -> 42.5 | L29: =IFERROR(__xludf.DUMMYFUNCTION("""COMPUTED_VALUE"""),"Action") -> Action | N29: =IFERROR(__xludf.DUMMYFUNCTION("""COMPUTED_VALUE"""),"Game Pass Essential (12/6/23)") -> Game Pass Essential (12/6/23) | O29: =IFERROR(__xludf.DUMMYFUNCTION("""COMPUTED_VALUE"""),"M") -> M | P29: =IFERROR(__xludf.DUMMYFUNCTION("""COMPUTED_VALUE"""),"Use of Alcohol, Blood and Gore, Mild Sexual Themes, Language, Intense Violence") -> Use of Alcohol, Blood and Gore, Mild Sexual Themes, Language, Intense Violence
A30: =IFERROR(__xludf.DUMMYFUNCTION("""COMPUTED_VALUE"""),"Unpacking") -> Unpacking | B30: =IFERROR(__xludf.DUMMYFUNCTION("""COMPUTED_VALUE"""),"Xbox / PC") -> Xbox / PC | C30: =IFERROR(__xludf.DUMMYFUNCTION("""COMPUTED_VALUE"""),"Touch Controls") -> Touch Controls | D30: =IFERROR(__xludf.DUMMYFUNCTION("""COMPUTED_VALUE"""),"Active") -> Active | E30: =IFERROR(__xludf.DUMMYFUNCTION("""COMPUTED_VALUE"""),44502.0) -> 44502 | G30: =IFERROR(__xludf.DUMMYFUNCTION("""COMPUTED_VALUE"""),47.43333333333334) -> 47.433333 | H30: =IFERROR(__xludf.DUMMYFUNCTION("""COMPUTED_VALUE"""),44502.0) -> 44502 | I30: =IFERROR(__xludf.DUMMYFUNCTION("""COMPUTED_VALUE"""),0.0) -> 0 | J30: =IFERROR(__xludf.DUMMYFUNCTION("""COMPUTED_VALUE"""),82.0) -> 82 | K30: =IFERROR(__xludf.DUMMYFUNCTION("""COMPUTED_VALUE"""),3.5) -> 3.5 | L30: =IFERROR(__xludf.DUMMYFUNCTION("""COMPUTED_VALUE"""),"Simulation / Puzzle") -> Simulation / Puzzle | N30: =IFERROR(__xludf.DUMMYFUNCTION("""COMPUTED_VALUE"""),"Game Pass Essential launch title (9/14/23)") -> Game Pass Essential launch title (9/14/23) | O30: =IFERROR(__xludf.DUMMYFUNCTION("""COMPUTED_VALUE"""),"E") -> E
A31: =IFERROR(__xludf.DUMMYFUNCTION("""COMPUTED_VALUE"""),"Superliminal") -> Superliminal | B31: =IFERROR(__xludf.DUMMYFUNCTION("""COMPUTED_VALUE"""),"Xbox / PC") -> Xbox / PC | C31: =IFERROR(__xludf.DUMMYFUNCTION("""COMPUTED_VALUE"""),"Touch Controls") -> Touch Controls | D31: =IFERROR(__xludf.DUMMYFUNCTION("""COMPUTED_VALUE"""),"Active") -> Active | E31: =IFERROR(__xludf.DUMMYFUNCTION("""COMPUTED_VALUE"""),44455.0) -> 44455 | G31: =IFERROR(__xludf.DUMMYFUNCTION("""COMPUTED_VALUE"""),48.96666666666667) -> 48.966667 | H31: =IFERROR(__xludf.DUMMYFUNCTION("""COMPUTED_VALUE"""),43781.0) -> 43781 | I31: =IFERROR(__xludf.DUMMYFUNCTION("""COMPUTED_VALUE"""),1.8444444444444446) -> 1.8444444 | J31: =IFERROR(__xludf.DUMMYFUNCTION("""COMPUTED_VALUE"""),77.0) -> 77 | K31: =IFERROR(__xludf.DUMMYFUNCTION("""COMPUTED_VALUE"""),2.5) -> 2.5 | L31: =IFERROR(__xludf.DUMMYFUNCTION("""COMPUTED_VALUE"""),"Puzzle") -> Puzzle | N31: =IFERROR(__xludf.DUMMYFUNCTION("""COMPUTED_VALUE"""),"Game Pass Essential launch title (9/14/23)") -> Game Pass Essential launch title (9/14/23) | O31: =IFERROR(__xludf.DUMMYFUNCTION("""COMPUTED_VALUE"""),"E") -> E | P31: =IFERROR(__xludf.DUMMYFUNCTION("""COMPUTED_VALUE"""),"Mild Blood") -> Mild Blood
A32: =IFERROR(__xludf.DUMMYFUNCTION("""COMPUTED_VALUE"""),"Deep Rock Galactic") -> Deep Rock Galactic | B32: =IFERROR(__xludf.DUMMYFUNCTION("""COMPUTED_VALUE"""),"Xbox / PC") -> Xbox / PC | C32: =IFERROR(__xludf.DUMMYFUNCTION("""COMPUTED_VALUE"""),"M+KB") -> M+KB | D32: =IFERROR(__xludf.DUMMYFUNCTION("""COMPUTED_VALUE"""),"Active") -> Active | E32: =IFERROR(__xludf.DUMMYFUNCTION("""COMPUTED_VALUE"""),44140.0) -> 44140 | G32: =IFERROR(__xludf.DUMMYFUNCTION("""COMPUTED_VALUE"""),59.333333333333336) -> 59.333333 | H32: =IFERROR(__xludf.DUMMYFUNCTION("""COMPUTED_VALUE"""),43964.0) -> 43964 | I32: =IFERROR(__xludf.DUMMYFUNCTION("""COMPUTED_VALUE"""),0.4777777777777778) -> 0.47777778 | J32: =IFERROR(__xludf.DUMMYFUNCTION("""COMPUTED_VALUE"""),84.0) -> 84 | K32: =IFERROR(__xludf.DUMMYFUNCTION("""COMPUTED_VALUE"""),119.0) -> 119 | L32: =IFERROR(__xludf.DUMMYFUNCTION("""COMPUTED_VALUE"""),"First-Person Shooter") -> First-Person Shooter | N32: =IFERROR(__xludf.DUMMYFUNCTION("""COMPUTED_VALUE"""),"Game Pass Essential (4/23/24)") -> Game Pass Essential (4/23/24) | O32: =IFERROR(__xludf.DUMMYFUNCTION("""COMPUTED_VALUE"""),"T") -> T | P32: =IFERROR(__xludf.DUMMYFUNCTION("""COMPUTED_VALUE"""),"Violence, Blood, Use of Alcohol, Language") -> Violence, Blood, Use of Alcohol, Language
A33: =IFERROR(__xludf.DUMMYFUNCTION("""COMPUTED_VALUE"""),"Tom Clancy's Rainbow Six: Siege - Deluxe Edition") -> Tom Clancy's Rainbow Six: Siege - Deluxe Edition | B33: =IFERROR(__xludf.DUMMYFUNCTION("""COMPUTED_VALUE"""),"Xbox / PC") -> Xbox / PC | C33: =IFERROR(__xludf.DUMMYFUNCTION("""COMPUTED_VALUE"""),"Yes") -> Yes | D33: =IFERROR(__xludf.DUMMYFUNCTION("""COMPUTED_VALUE"""),"Active") -> Active | E33: =IFERROR(__xludf.DUMMYFUNCTION("""COMPUTED_VALUE"""),44126.0) -> 44126 | G33: =IFERROR(__xludf.DUMMYFUNCTION("""COMPUTED_VALUE"""),59.766666666666666) -> 59.766667 | H33: =IFERROR(__xludf.DUMMYFUNCTION("""COMPUTED_VALUE"""),42339.0) -> 42339 | I33: =IFERROR(__xludf.DUMMYFUNCTION("""COMPUTED_VALUE"""),4.891666666666667) -> 4.8916667 | J33: =IFERROR(__xludf.DUMMYFUNCTION("""COMPUTED_VALUE"""),74.0) -> 74 | K33: =IFERROR(__xludf.DUMMYFUNCTION("""COMPUTED_VALUE"""),7.5) -> 7.5 | L33: =IFERROR(__xludf.DUMMYFUNCTION("""COMPUTED_VALUE"""),"First-Person Shooter") -> First-Person Shooter | M33: =IFERROR(__xludf.DUMMYFUNCTION("""COMPUTED_VALUE"""),"Optimized") -> Optimized | N33: =IFERROR(__xludf.DUMMYFUNCTION("""COMPUTED_VALUE"""),"Ubisoft Connect launcher, joined PC 1/20/21") -> Ubisoft Connect launcher, joined PC 1/20/21 | O33: =IFERROR(__xludf.DUMMYFUNCTION("""COMPUTED_VALUE"""),"M") -> M | P33: =IFERROR(__xludf.DUMMYFUNCTION("""COMPUTED_VALUE"""),"Blood, Drug Reference, Strong Language, Violence") -> Blood, Drug Reference, Strong Language, Violence

Sheet Xbox Game Studios
A1: Published or Developed by Subsidiary | B1: Studio | C1: Platform | D1: Added | E1: Publisher | F1: Studio | G1: Date | H1: Closed
A2: The Outer Worlds 2 | B2: Obsidian Entertainment | C2: =VLOOKUP(A2,'Master List'!A:E,2,) -> Xbox / PC | D2: =VLOOKUP(A2,'Master List'!A:E,5,) -> 45959 | F2: Xbox Game Studios Publishing | G2: 2000
A3: Ninja Gaiden 4 | B3: Xbox Game Studios (Publisher) | C3: =VLOOKUP(A3,'Master List'!A:E,2,) -> Xbox / PC | D3: =VLOOKUP(A3,'Master List'!A:E,5,) -> 45951 | F3: Turn 10 Studios | G3: 2001
A4: Gears of War: Reloaded | B4: The Coalition | C4: =VLOOKUP(A4,'Master List'!A:E,2,) -> Xbox / PC | D4: =VLOOKUP(A4,'Master List'!A:E,5,) -> 45895 | F4: Rare | G4: 2002
A5: Caesar III | B5: =VLOOKUP(A5,'Master List'!A:N,14,) -> Retro Classics: Windows 9x | C5: =VLOOKUP(A5,'Master List'!A:E,2,) -> Xbox / PC | D5: =VLOOKUP(A5,'Master List'!A:E,5,) -> 45883 | F5: 343 Industries | G5: 2007
A6: Climber 5 | B6: =VLOOKUP(A6,'Master List'!A:N,14,) -> Retro Classics: Atari 2600 | C6: =VLOOKUP(A6,'Master List'!A:E,2,) -> Xbox / PC | D6: =VLOOKUP(A6,'Master List'!A:E,5,) -> 45883 | F6: The Coalition | G6: 2007
A7: The Colonel's Bequest | B7: =VLOOKUP(A7,'Master List'!A:N,14,) -> Retro Classics: Amiga | C7: =VLOOKUP(A7,'Master List'!A:E,2,) -> Xbox / PC | D7: =VLOOKUP(A7,'Master List'!A:E,5,) -> 45883 | F7: Mojang Studios | G7: 2014
A8: Private Eye | B8: =VLOOKUP(A8,'Master List'!A:N,14,) -> Retro Classics: Atari 2600 | C8: =VLOOKUP(A8,'Master List'!A:E,2,) -> Xbox / PC | D8: =VLOOKUP(A8,'Master List'!A:E,5,) -> 45883 | F8: Compulsion Games | G8: 2018
A9: Oystron | B9: =VLOOKUP(A9,'Master List'!A:N,14,) -> Retro Classics: Atari 2600 | C9: =VLOOKUP(A9,'Master List'!A:E,2,) -> Xbox / PC | D9: =VLOOKUP(A9,'Master List'!A:E,5,) -> 45883 | F9: The Initiative | G9: 2018
A10: Shootin' Gallery | B10: =VLOOKUP(A10,'Master List'!A:N,14,) -> Retro Classics: Atari 2600 | C10: =VLOOKUP(A10,'Master List'!A:E,2,) -> Xbox / PC | D10: =VLOOKUP(A10,'Master List'!A:E,5,) -> 45883 | F10: inXile Entertainment | G10: 2018
A11: Wing War | B11: =VLOOKUP(A11,'Master List'!A:N,14,) -> Retro Classics: Atari 2600 | C11: =VLOOKUP(A11,'Master List'!A:E,2,) -> Xbox / PC | D11: =VLOOKUP(A11,'Master List'!A:E,5,) -> 45883 | F11: Ninja Theory | G11: 2018
A12: Heretic + Hexen | B12: Raven Software (Activision Blizzard King) | C12: =VLOOKUP(A12,'Master List'!A:E,2,) -> Xbox / PC | D12: =VLOOKUP(A12,'Master List'!A:E,5,) -> 45876 | F12: Obsidian Entertainment | G12: 2018
A13: Grounded 2 (Game Preview) | B13: Obsidian Entertainment | C13: =VLOOKUP(A13,'Master List'!A:E,2,) -> Xbox / PC | D13: =VLOOKUP(A13,'Master List'!A:E,5,) -> 45867 | F13: Playground Games | G13: 2018
A14: Caesar | B14: =VLOOKUP(A14,'Master List'!A:N,14,) -> Retro Classics: Amiga | C14: =VLOOKUP(A14,'Master List'!A:E,2,) -> Xbox / PC | D14: =VLOOKUP(A14,'Master List'!A:E,5,) -> 45859 | F14: Undead Labs | G14: 2018
A15: Conquests of Camelot: The Search for the Grail | B15: =VLOOKUP(A15,'Master List'!A:N,14,) -> Retro Classics: Amiga | C15: =VLOOKUP(A15,'Master List'!A:E,2,) -> Xbox / PC | D15: =VLOOKUP(A15,'Master List'!A:E,5,) -> 45859 | F15: Double Fine Productions | G15: 2019
A16: Gabriel Knight: Sins of the Fathers | B16: =VLOOKUP(A16,'Master List'!A:N,14,) -> Retro Classics: DOS | C16: =VLOOKUP(A16,'Master List'!A:E,2,) -> Xbox / PC | D16: =VLOOKUP(A16,'Master List'!A:E,5,) -> 45859 | F16: World's Edge | G16: 2019
A17: Hard Head | B17: =VLOOKUP(A17,'Master List'!A:N,14,) -> Retro Classics: Atari 2600 | C17: =VLOOKUP(A17,'Master List'!A:E,2,) -> Xbox / PC | D17: =VLOOKUP(A17,'Master List'!A:E,5,) -> 45859 | E17: ZeniMax Media/Bethesda Softworks | F17: Bethesda Game Studios | G17: 2021
A18: Okie Dokie | B18: =VLOOKUP(A18,'Master List'!A:N,14,) -> Retro Classics: Atari 2600 | C18: =VLOOKUP(A18,'Master List'!A:E,2,) -> Xbox / PC | D18: =VLOOKUP(A18,'Master List'!A:E,5,) -> 45859 | E18: ZeniMax Media/Bethesda Softworks | F18: ZeniMax Online Studios | G18: 2021
A19: Skate Boardin' | B19: =VLOOKUP(A19,'Master List'!A:N,14,) -> Retro Classics: Atari 2600 | C19: =VLOOKUP(A19,'Master List'!A:E,2,) -> Xbox / PC | D19: =VLOOKUP(A19,'Master List'!A:E,5,) -> 45859 | E19: ZeniMax Media/Bethesda Softworks | F19: Arkane Studios (Austin office closed 2024) | G19: 2021
A20: Skeleton+ | B20: =VLOOKUP(A20,'Master List'!A:N,14,) -> Retro Classics: Atari 2600 | C20: =VLOOKUP(A20,'Master List'!A:E,2,) -> Xbox / PC | D20: =VLOOKUP(A20,'Master List'!A:E,5,) -> 45859 | E20: ZeniMax Media/Bethesda Softworks | F20: id Software | G20: 2021
A21: Cosmic Commuter | B21: =VLOOKUP(A21,'Master List'!A:N,14,) -> Retro Classics: Atari 2600 | C21: =VLOOKUP(A21,'Master List'!A:E,2,) -> Xbox / PC | D21: =VLOOKUP(A21,'Master List'!A:E,5,) -> 45839 | E21: ZeniMax Media/Bethesda Softworks | F21: ZeniMax Media/Bethesda Softworks | G21: MachineGames | H21: 2021
A22: Heart of China | B22: =VLOOKUP(A22,'Master List'!A:N,14,) -> Retro Classics: DOS | C22: =VLOOKUP(A22,'Master List'!A:E,2,) -> Xbox / PC | D22: =VLOOKUP(A22,'Master List'!A:E,5,) -> 45839 | E22: ZeniMax Media/Bethesda Softworks | F22: Tango Gameworks | G22: 2021 | H22: 2024
A23: Skiing | B23: =VLOOKUP(A23,'Master List'!A:N,14,) -> Retro Classics: Atari 2600 | C23: =VLOOKUP(A23,'Master List'!A:E,2,) -> Xbox / PC | D23: =VLOOKUP(A23,'Master List'!A:E,5,) -> 45839 | E23: ZeniMax Media/Bethesda Softworks | F23: Alpha Dog Games | G23: 2021 | H23: 2024
A24: Solar Storm | B24: =VLOOKUP(A24,'Master List'!A:N,14,) -> Retro Classics: Atari 2600 | C24: =VLOOKUP(A24,'Master List'!A:E,2,) -> Xbox / PC | D24: =VLOOKUP(A24,'Master List'!A:E,5,) -> 45839 | E24: ZeniMax Media/Bethesda Softworks | F24: Roundhouse Studios (Absorbed by ZeniMax) | G24: 2021 | H24: 2024
A25: Subterranea | B25: =VLOOKUP(A25,'Master List'!A:N,14,) -> Retro Classics: Atari 2600 | C25: =VLOOKUP(A25,'Master List'!A:E,2,) -> Xbox / PC | D25: =VLOOKUP(A25,'Master List'!A:E,5,) -> 45839 | E25: Activision Blizzard King | F25: Infinity Ward | G25: 2023
A26: Call of Duty: WWII | B26: Sledgehammer Games (Activision Blizzard King) | C26: =VLOOKUP(A26,'Master List'!A:E,2,) -> Xbox / PC | D26: =VLOOKUP(A26,'Master List'!A:E,5,) -> 45838 | E26: Activision Blizzard King | F26: Treyarch | G26: 2023
A27: Warcraft I: Remastered | B27: Blizzard Entertainment | C27: =VLOOKUP(A27,'Master List'!A:E,2,) -> PC | D27: =VLOOKUP(A27,'Master List'!A:E,5,) -> 45834 | E27: Activision Blizzard King | F27: Sledgehammer Games | G27: 2023
A28: Warcraft II: Remastered | B28: Blizzard Entertainment | C28: =VLOOKUP(A28,'Master List'!A:E,2,) -> PC | D28: =VLOOKUP(A28,'Master List'!A:E,5,) -> 45834 | E28: Activision Blizzard King | F28: Raven Software | G28: 2023
A29: Warcraft III: Reforged | B29: Blizzard Entertainment | C29: =VLOOKUP(A29,'Master List'!A:E,2,) -> PC | D29: =VLOOKUP(A29,'Master List'!A:E,5,) -> 45834 | E29: Activision Blizzard King | F29: High Moon Studios | G29: 2023
