Workbook
Name Lake: PC!$B$467
Name b: 'Master List'!$A:$A
Name dragon: 'Master List'!$A$1829
Name assass: 'Master List'!$A$1046
Name banjo: 'Copy of Removed'!$I$110
Name onrush: 'Master List'!$A$1327
Name Tiny: 'Xbox Game Studios'!$A$1
Name civ: PC!$A$1
Name civ: #REF!
Name gris: 'Master List'!$A$1732
Name Lake: #REF!
Name PC: 'Master List'!$A$2
Name hellslinger: xCloud!$K$85
Name persona: 'Copy of Removed'!$H$288:$H$295
Name chain: 'Master List'!$A$1
Name persona: Removed!$H$288:$H$295
Name banjo: Removed!$I$110
Name banjo: 'Master List'!$I$1356
Name YEARDUR: LAMBDA(start, end, lambda(s, e, if(s > e, -1 , 1 ) * yearfrac(s, e, 4))(if(isblank(start),today(),start), if(isblank(end),today(),end)))
Name MONTHDUR: LAMBDA(start, end, YEARDUR(start, end) * 12)

Sheet Master List
A1: Complete Game Pass Master List by u/ABattleVet | B1: =COUNTIFS(D2:D2289,"Active",B2:B2289,"<>")+COUNTIF(D2:D2289,"Leaving Soon") -> 741 | C1: Games with Gold | E1: GPU | H1: Playstation Plus | L1: =Suggestions!A1 -> Coming Soon | N1: The community can add games to cross play/play anywhere | P1: Public Notes | R1: GP Premium (10/1/25 Standard 9/12/24) | U1: GP Essential (10/1/25 Core 9/14/23)
A2: Game | B2: System | C2: xCloud | D2: Status | E2: Added | F2: Removed | G2: Months | H2: Release | I2: Age | J2: Metacritic | K2: Completion | L2: Genre | M2: Series X|S | N2: Owner Notes | O2: ESRB | P2: ESRB Content Descriptors | Q2: Community Notes | R2: Status | S2: Added | T2: Delay | U2: Added | V2: Delay
A3: Gears of War: E-Day | B3: Xbox / PC | C3: Yes | D3: =IF(E3>TODAY(),"Coming Soon",IF(F3="","Active",IF(F3>TODAY(),"Leaving Soon","Removed"))) -> Active | E3: 46301 | G3: =MONTHDUR(E3,F3) -> 0 | H3: 46301 | I3: =YEARDUR(H3,E3) -> 0 | L3: Shooter | M3: Exclusive | N3: Handheld Optimized | R3: =IF(S3="","TBD",IF(S3>TODAY(),"Coming Soon",IF(F3="","Active",IF(F3>TODAY(),"Leaving Soon","Removed")))) -> TBD | T3: =MONTHDUR(E3,S3) -> 0
A4: Minecraft Dungeons II | B4: Xbox / PC | C4: Yes | D4: =IF(E4>TODAY(),"Coming Soon",IF(F4="","Active",IF(F4>TODAY(),"Leaving Soon","Removed"))) -> Active | E4: 46294 | G4: =MONTHDUR(E4,F4) -> 0.23333333 | H4: 46294 | I4: =YEARDUR(H4,E4) -> 0 | L4: Action-Adventure | N4: Handheld Optimized | R4: =IF(S4="","TBD",IF(S4>TODAY(),"Coming Soon",IF(F4="","Active",IF(F4>TODAY(),"Leaving Soon","Removed")))) -> TBD | T4: =MONTHDUR(E4,S4) -> 0.23333333
A5: Mad King Redemption | B5: Xbox / PC | C5: Yes | D5: =IF(E5>TODAY(),"Coming Soon",IF(F5="","Active",IF(F5>TODAY(),"Leaving Soon","Removed"))) -> Active | E5: 46288 | G5: =MONTHDUR(E5,F5) -> 0.43333333 | H5: 46288 | I5: =YEARDUR(H5,E5) -> 0 | L5: Action-Adventure | M5: Exclusive | N5: Handheld Optimized | R5: =IF(S5="","TBD",IF(S5>TODAY(),"Coming Soon",IF(F5="","Active",IF(F5>TODAY(),"Leaving Soon","Removed")))) -> Active | S5: =E5 -> 46288 | T5: =MONTHDUR(E5,S5) -> 0
A6: Dune: Awakening | B6: Xbox / PC | C6: Yes | D6: =IF(E6>TODAY(),"Coming Soon",IF(F6="","Active",IF(F6>TODAY(),"Leaving Soon","Removed"))) -> Active | E6: 46287 | G6: =MONTHDUR(E6,F6) -> 0.46666667 | H6: 45818 | I6: =YEARDUR(H6,E6) -> 1.2833333 | J6: 78 | K6: 114 | L6: Action-Adventure | M6: Exclusive | N6: Handheld Optimized | R6: =IF(S6="","TBD",IF(S6>TODAY(),"Coming Soon",IF(F6="","Active",IF(F6>TODAY(),"Leaving Soon","Removed")))) -> Active | S6: =E6 -> 46287 | T6: =MONTHDUR(E6,S6) -> 0
A7: Well Dweller | B7: Xbox / PC | C7: Yes | D7: =IF(E7>TODAY(),"Coming Soon",IF(F7="","Active",IF(F7>TODAY(),"Leaving Soon","Removed"))) -> Active | E7: 46287 | G7: =MONTHDUR(E7,F7) -> 0.46666667 | H7: 46287 | I7: =YEARDUR(H7,E7) -> 0 | L7: Action-Adventure | N7: Handheld Optimized | R7: =IF(S7="","TBD",IF(S7>TODAY(),"Coming Soon",IF(F7="","Active",IF(F7>TODAY(),"Leaving Soon","Removed")))) -> TBD | T7: =MONTHDUR(E7,S7) -> 0.46666667
A8: Shape of Dreams | B8: Xbox / PC | C8: Yes | D8: =IF(E8>TODAY(),"Coming Soon",IF(F8="","Active",IF(F8>TODAY(),"Leaving Soon","Removed"))) -> Active | E8: 46282 | G8: =MONTHDUR(E8,F8) -> 0.63333333 | H8: 45910 | I8: =YEARDUR(H8,E8) -> 1.0194444 | J8: 84 | K8: 9 | L8: RPG | R8: =IF(S8="","TBD",IF(S8>TODAY(),"Coming Soon",IF(F8="","Active",IF(F8>TODAY(),"Leaving Soon","Removed")))) -> Active | S8: =E8 -> 46282 | T8: =MONTHDUR(E8,S8) -> 0
A9: Kernel Hearts | B9: Xbox / PC | C9: Yes | D9: =IF(E9>TODAY(),"Coming Soon",IF(F9="","Active",IF(F9>TODAY(),"Leaving Soon","Removed"))) -> Active | E9: 46282 | G9: =MONTHDUR(E9,F9) -> 0.63333333 | H9: 46282 | I9: =YEARDUR(H9,E9) -> 0 | L9: RPG | M9: Exclusive | R9: =IF(S9="","TBD",IF(S9>TODAY(),"Coming Soon",IF(F9="","Active",IF(F9>TODAY(),"Leaving Soon","Removed")))) -> TBD | T9: =MONTHDUR(E9,S9) -> 0.63333333
A10: RuneScape: Dragonwilds | B10: Xbox / PC | C10: Yes | D10: =IF(E10>TODAY(),"Coming Soon",IF(F10="","Active",IF(F10>TODAY(),"Leaving Soon","Removed"))) -> Active | E10: 46280 | G10: =MONTHDUR(E10,F10) -> 0.7 | H10: 46280 | I10: =YEARDUR(H10,E10) -> 0 | K10: 23 | L10: Action-Adventure | M10: Exclusive | R10: =IF(S10="","TBD",IF(S10>TODAY(),"Coming Soon",IF(F10="","Active",IF(F10>TODAY(),"Leaving Soon","Removed")))) -> Active | S10: =E10 -> 46280 | T10: =MONTHDUR(E10,S10) -> 0
A11: The Royal Writ | B11: Xbox / PC | C11: Yes | D11: =IF(E11>TODAY(),"Coming Soon",IF(F11="","Active",IF(F11>TODAY(),"Leaving Soon","Removed"))) -> Active | E11: 46275 | G11: =MONTHDUR(E11,F11) -> 0.86666667 | H11: 45876 | I11: =YEARDUR(H11,E11) -> 1.0916667 | J11: 80 | K11: 5 | L11: Card Battle | M11: Exclusive | N11: Handheld Optimized | R11: =IF(S11="","TBD",IF(S11>TODAY(),"Coming Soon",IF(F11="","Active",IF(F11>TODAY(),"Leaving Soon","Removed")))) -> Active | S11: =E11 -> 46275 | T11: =MONTHDUR(E11,S11) -> 0
A12: Virtua Fighter 5 R.E.V.O. World Stage | B12: Xbox / PC | C12: Yes | D12: =IF(E12>TODAY(),"Coming Soon",IF(F12="","Active",IF(F12>TODAY(),"Leaving Soon","Removed"))) -> Active | E12: 46275 | G12: =MONTHDUR(E12,F12) -> 0.86666667 | H12: 45960 | I12: =YEARDUR(H12,E12) -> 0.86111111 | J12: 78 | K12: 1 | L12: Fighting | M12: Exclusive | R12: =IF(S12="","TBD",IF(S12>TODAY(),"Coming Soon",IF(F12="","Active",IF(F12>TODAY(),"Leaving Soon","Removed")))) -> Active | S12: =E12 -> 46275 | T12: =MONTHDUR(E12,S12) -> 0
A13: Call of Duty: Black Ops Cold War | B13: Xbox / PC | C13: Yes | D13: =IF(E13>TODAY(),"Coming Soon",IF(F13="","Active",IF(F13>TODAY(),"Leaving Soon","Removed"))) -> Active | E13: 46273 | G13: =MONTHDUR(E13,F13) -> 0.93333333 | H13: 44148 | I13: =YEARDUR(H13,E13) -> 5.8194444 | J13: 76 | K13: 5.5 | L13: Shooter | R13: =IF(S13="","TBD",IF(S13>TODAY(),"Coming Soon",IF(F13="","Active",IF(F13>TODAY(),"Leaving Soon","Removed")))) -> Active | S13: =E13 -> 46273 | T13: =MONTHDUR(E13,S13) -> 0
A14: Speedrunners 2: King of Speed | B14: Xbox / PC | C14: Yes | D14: =IF(E14>TODAY(),"Coming Soon",IF(F14="","Active",IF(F14>TODAY(),"Leaving Soon","Removed"))) -> Active | E14: 46268 | G14: =MONTHDUR(E14,F14) -> 1.1 | H14: 46268 | I14: =YEARDUR(H14,E14) -> 0 | K14: 3 | L14: Racing | M14: Exclusive | R14: =IF(S14="","TBD",IF(S14>TODAY(),"Coming Soon",IF(F14="","Active",IF(F14>TODAY(),"Leaving Soon","Removed")))) -> TBD | T14: =MONTHDUR(E14,S14) -> 1.1
A15: Shelldiver | B15: Xbox / PC | C15: Yes | D15: =IF(E15>TODAY(),"Coming Soon",IF(F15="","Active",IF(F15>TODAY(),"Leaving Soon","Removed"))) -> Active | E15: 46266 | G15: =MONTHDUR(E15,F15) -> 1.1666667 | H15: 45977 | I15: =YEARDUR(H15,E15) -> 0.79166667 | K15: 4 | L15: Platformer | R15: =IF(S15="","TBD",IF(S15>TODAY(),"Coming Soon",IF(F15="","Active",IF(F15>TODAY(),"Leaving Soon","Removed")))) -> Active | S15: =E15 -> 46266 | T15: =MONTHDUR(E15,S15) -> 0
A16: Resonance: A Plague Tale Legacy | B16: Xbox / PC | C16: Yes | D16: =IF(E16>TODAY(),"Coming Soon",IF(F16="","Active",IF(F16>TODAY(),"Leaving Soon","Removed"))) -> Active | E16: 46261 | G16: =MONTHDUR(E16,F16) -> 1.3 | H16: 46261 | I16: =YEARDUR(H16,E16) -> 0 | J16: 78 | K16: 12 | L16: Action-Adventure | M16: Exclusive | N16: Handheld Optimized | R16: =IF(S16="","TBD",IF(S16>TODAY(),"Coming Soon",IF(F16="","Active",IF(F16>TODAY(),"Leaving Soon","Removed")))) -> TBD | T16: =MONTHDUR(E16,S16) -> 1.3
A17: Blood Dungeon | B17: Xbox / PC | C17: Yes | D17: =IF(E17>TODAY(),"Coming Soon",IF(F17="","Active",IF(F17>TODAY(),"Leaving Soon","Removed"))) -> Active | E17: 46259 | G17: =MONTHDUR(E17,F17) -> 1.3666667 | H17: 46259 | I17: =YEARDUR(H17,E17) -> 0 | J17: 74 | K17: 2 | L17: Action-Adventure | M17: Exclusive | R17: =IF(S17="","TBD",IF(S17>TODAY(),"Coming Soon",IF(F17="","Active",IF(F17>TODAY(),"Leaving Soon","Removed")))) -> TBD | T17: =MONTHDUR(E17,S17) -> 1.3666667
A18: Vapor World: Over the Mind (Game Preview) | B18: Xbox / PC | C18: Yes | D18: =IF(E18>TODAY(),"Coming Soon",IF(F18="","Active",IF(F18>TODAY(),"Leaving Soon","Removed"))) -> Active | E18: 46253 | G18: =MONTHDUR(E18,F18) -> 1.5666667 | H18: 46253 | I18: =YEARDUR(H18,E18) -> 0 | K18: 12 | L18: Action-Adventure | R18: =IF(S18="","TBD",IF(S18>TODAY(),"Coming Soon",IF(F18="","Active",IF(F18>TODAY(),"Leaving Soon","Removed")))) -> TBD | T18: =MONTHDUR(E18,S18) -> 1.5666667
A19: Cricket 26 | B19: Xbox / PC | C19: Yes | D19: =IF(E19>TODAY(),"Coming Soon",IF(F19="","Active",IF(F19>TODAY(),"Leaving Soon","Removed"))) -> Active | E19: 46247 | G19: =MONTHDUR(E19,F19) -> 1.7666667 | H19: 45974 | I19: =YEARDUR(H19,E19) -> 0.75 | J19: 75 | K19: 33 | L19: Sports | R19: =IF(S19="","TBD",IF(S19>TODAY(),"Coming Soon",IF(F19="","Active",IF(F19>TODAY(),"Leaving Soon","Removed")))) -> Active | S19: =E19 -> 46247 | T19: =MONTHDUR(E19,S19) -> 0
A20: Sandustry (Game Preview) | B20: PC | D20: =IF(E20>TODAY(),"Coming Soon",IF(F20="","Active",IF(F20>TODAY(),"Leaving Soon","Removed"))) -> Active | E20: 46247 | G20: =MONTHDUR(E20,F20) -> 1.7666667 | H20: 46247 | I20: =YEARDUR(H20,E20) -> 0 | K20: 8 | L20: Simulation | R20: =IF(S20="","TBD",IF(S20>TODAY(),"Coming Soon",IF(F20="","Active",IF(F20>TODAY(),"Leaving Soon","Removed")))) -> TBD | T20: =MONTHDUR(E20,S20) -> 1.7666667
A21: Date Everything! | B21: Xbox / PC | C21: Yes | D21: =IF(E21>TODAY(),"Coming Soon",IF(F21="","Active",IF(F21>TODAY(),"Leaving Soon","Removed"))) -> Active | E21: 46245 | G21: =MONTHDUR(E21,F21) -> 1.8333333 | H21: 45825 | I21: =YEARDUR(H21,E21) -> 1.15 | J21: 78 | K21: 15 | L21: Simulation | M21: Exclusive | N21: Handheld Optimized | R21: =IF(S21="","TBD",IF(S21>TODAY(),"Coming Soon",IF(F21="","Active",IF(F21>TODAY(),"Leaving Soon","Removed")))) -> Active | S21: =E21 -> 46245 | T21: =MONTHDUR(E21,S21) -> 0
A22: Beast of Reincarnation | B22: Xbox / PC | C22: Yes | D22: =IF(E22>TODAY(),"Coming Soon",IF(F22="","Active",IF(F22>TODAY(),"Leaving Soon","Removed"))) -> Active | E22: 46238 | G22: =MONTHDUR(E22,F22) -> 2.0666667 | H22: 46238 | I22: =YEARDUR(H22,E22) -> 0 | J22: 72 | K22: 23 | L22: RPG | M22: Exclusive | N22: Handheld Optimized | R22: =IF(S22="","TBD",IF(S22>TODAY(),"Coming Soon",IF(F22="","Active",IF(F22>TODAY(),"Leaving Soon","Removed")))) -> TBD | T22: =MONTHDUR(E22,S22) -> 2.0666667
A23: Tears of Metal (Game Preview) | B23: PC | D23: =IF(E23>TODAY(),"Coming Soon",IF(F23="","Active",IF(F23>TODAY(),"Leaving Soon","Removed"))) -> Active | E23: 46225 | G23: =MONTHDUR(E23,F23) -> 2.4666667 | H23: 46225 | I23: =YEARDUR(H23,E23) -> 0 | J23: 75 | K23: 4 | L23: Action-Adventure | R23: =IF(S23="","TBD",IF(S23>TODAY(),"Coming Soon",IF(F23="","Active",IF(F23>TODAY(),"Leaving Soon","Removed")))) -> TBD | T23: =MONTHDUR(E23,S23) -> 2.4666667
A24: Corsair Cove | B24: PC | D24: =IF(E24>TODAY(),"Coming Soon",IF(F24="","Active",IF(F24>TODAY(),"Leaving Soon","Removed"))) -> Active | E24: 46234 | G24: =MONTHDUR(E24,F24) -> 2.2 | H24: 46234 | I24: =YEARDUR(H24,E24) -> 0 | J24: 70 | K24: 29 | L24: Simulation | R24: =IF(S24="","TBD",IF(S24>TODAY(),"Coming Soon",IF(F24="","Active",IF(F24>TODAY(),"Leaving Soon","Removed")))) -> TBD | T24: =MONTHDUR(E24,S24) -> 2.2
A25: Mistfall Hunter | B25: Xbox / PC | C25: Yes | D25: =IF(E25>TODAY(),"Coming Soon",IF(F25="","Active",IF(F25>TODAY(),"Leaving Soon","Removed"))) -> Active | E25: 46233 | G25: =MONTHDUR(E25,F25) -> 2.2 | H25: 46233 | I25: =YEARDUR(H25,E25) -> 0 | J25: 70 | L25: RPG | M25: Exclusive | R25: =IF(S25="","TBD",IF(S25>TODAY(),"Coming Soon",IF(F25="","Active",IF(F25>TODAY(),"Leaving Soon","Removed")))) -> TBD | T25: =MONTHDUR(E25,S25) -> 2.2
A26: Halo: Campaign Evolved | B26: Xbox / PC | C26: Yes | D26: =IF(E26>TODAY(),"Coming Soon",IF(F26="","Active",IF(F26>TODAY(),"Leaving Soon","Removed"))) -> Active | E26: 46231 | G26: =MONTHDUR(E26,F26) -> 2.2666667 | H26: 46231 | I26: =YEARDUR(H26,E26) -> 0 | J26: 80 | K26: 9 | L26: Shooter | N26: Handheld Optimized | R26: =IF(S26="","TBD",IF(S26>TODAY(),"Coming Soon",IF(F26="","Active",IF(F26>TODAY(),"Leaving Soon","Removed")))) -> TBD | T26: =MONTHDUR(E26,S26) -> 2.2666667
A27: Conker: Live & Reloaded | B27: Xbox / PC | C27: Yes | D27: =IF(E27>TODAY(),"Coming Soon",IF(F27="","Active",IF(F27>TODAY(),"Leaving Soon","Removed"))) -> Active | E27: 46225 | G27: =MONTHDUR(E27,F27) -> 2.4666667 | H27: 38673 | I27: =YEARDUR(H27,E27) -> 20.680556 | J27: 82 | K27: 11 | L27: Action-Adventure | M27: Enhanced | N27: XBOX Backward Compatibility on PC (7/22/26) | R27: =IF(S27="","TBD",IF(S27>TODAY(),"Coming Soon",IF(F27="","Active",IF(F27>TODAY(),"Leaving Soon","Removed")))) -> Active | S27: =E27 -> 46225 | T27: =MONTHDUR(E27,S27) -> 0 | U27: 46225 | V27: =MONTHDUR(E27,U27) -> 0
A28: Hell is Us | B28: Xbox / PC | C28: Yes | D28: =IF(E28>TODAY(),"Coming Soon",IF(F28="","Active",IF(F28>TODAY(),"Leaving Soon","Removed"))) -> Active | E28: 46226 | G28: =MONTHDUR(E28,F28) -> 2.4333333 | H28: 45904 | I28: =YEARDUR(H28,E28) -> 0.88611111 | J28: 77 | K28: 18 | L28: Action-Adventure | M28: Exclusive | R28: =IF(S28="","TBD",IF(S28>TODAY(),"Coming Soon",IF(F28="","Active",IF(F28>TODAY(),"Leaving Soon","Removed")))) -> Active | S28: =E28 -> 46226 | T28: =MONTHDUR(E28,S28) -> 0
A29: Shift at Midnight | B29: Xbox / PC | C29: Yes | D29: =IF(E29>TODAY(),"Coming Soon",IF(F29="","Active",IF(F29>TODAY(),"Leaving Soon","Removed"))) -> Active | E29: 46225 | G29: =MONTHDUR(E29,F29) -> 2.4666667 | H29: 46225 | I29: =YEARDUR(H29,E29) -> 0 | J29: 80 | K29: 5 | L29: Horror | M29: Exclusive | R29: =IF(S29="","TBD",IF(S29>TODAY(),"Coming Soon",IF(F29="","Active",IF(F29>TODAY(),"Leaving Soon","Removed")))) -> TBD | T29: =MONTHDUR(E29,S29) -> 2.4666667
A30: The Planet Crafter | B30: Xbox / PC | C30: Yes | D30: =IF(E30>TODAY(),"Coming Soon",IF(F30="","Active",IF(F30>TODAY(),"Leaving Soon","Removed"))) -> Active | E30: 46224 | G30: =MONTHDUR(E30,F30) -> 2.5 | H30: 44644 | I30: =YEARDUR(H30,E30) -> 4.325 | J30: 81 | K30: 35 | L30: Sandbox | M30: Exclusive | R30: =IF(S30="","TBD",IF(S30>TODAY(),"Coming Soon",IF(F30="","Active",IF(F30>TODAY(),"Leaving Soon","Removed")))) -> Active | S30: =E30 -> 46224 | T30: =MONTHDUR(E30,S30) -> 0
A31: FixForce | B31: Xbox / PC | C31: Yes | D31: =IF(E31>TODAY(),"Coming Soon",IF(F31="","Active",IF(F31>TODAY(),"Leaving Soon","Removed"))) -> Active | E31: 46220 | G31: =MONTHDUR(E31,F31) -> 2.6333333 | H31: 46220 | I31: =YEARDUR(H31,E31) -> 0 | J31: 80 | L31: Platformer | M31: Exclusive | R31: =IF(S31="","TBD",IF(S31>TODAY(),"Coming Soon",IF(F31="","Active",IF(F31>TODAY(),"Leaving Soon","Removed")))) -> Active | S31: =E31 -> 46220 | T31: =MONTHDUR(E31,S31) -> 0
A32: Fogpiercer | B32: PC | D32: =IF(E32>TODAY(),"Coming Soon",IF(F32="","Active",IF(F32>TODAY(),"Leaving Soon","Removed"))) -> Active | E32: 46220 | G32: =MONTHDUR(E32,F32) -> 2.6333333 | H32: 46220 | I32: =YEARDUR(H32,E32) -> 0 | J32: 73 | K32: 5 | L32: Strategy | R32: =IF(S32="","TBD",IF(S32>TODAY(),"Coming Soon",IF(F32="","Active",IF(F32>TODAY(),"Leaving Soon","Removed")))) -> TBD | T32: =MONTHDUR(E32,S32) -> 2.6333333
A33: Mavrix by Matt Jones | B33: Xbox / PC | C33: Yes | D33: =IF(E33>TODAY(),"Coming Soon",IF(F33="","Active",IF(F33>TODAY(),"Leaving Soon","Removed"))) -> Active | E33: 46219 | G33: =MONTHDUR(E33,F33) -> 2.6666667 | H33: 46219 | I33: =YEARDUR(H33,E33) -> 0 | J33: 78 | L33: Racing | M33: Exclusive | N33: Handheld Optimized | R33: =IF(S33="","TBD",IF(S33>TODAY(),"Coming Soon",IF(F33="","Active",IF(F33>TODAY(),"Leaving Soon","Removed")))) -> Active | S33: =E33 -> 46219 | T33: =MONTHDUR(E33,S33) -> 0
A34: Denshattack! | B34: Xbox / PC | C34: Yes | D34: =IF(E34>TODAY(),"Coming Soon",IF(F34="","Active",IF(F34>TODAY(),"Leaving Soon","Removed"))) -> Active | E34: 46218 | G34: =MONTHDUR(E34,F34) -> 2.7 | H34: 45853 | I34: =YEARDUR(H34,E34) -> 1 | J34: 88 | K34: 9 | L34: Action-Adventure | M34: Exclusive | R34: =IF(S34="","TBD",IF(S34>TODAY(),"Coming Soon",IF(F34="","Active",IF(F34>TODAY(),"Leaving Soon","Removed")))) -> TBD | T34: =MONTHDUR(E34,S34) -> 2.7
A35: PBA Pro Bowling 2026 | B35: Xbox / PC | C35: Yes | D35: =IF(E35>TODAY(),"Coming Soon",IF(F35="","Active",IF(F35>TODAY(),"Leaving Soon","Removed"))) -> Active | E35: 46217 | G35: =MONTHDUR(E35,F35) -> 2.7333333 | H35: 46217 | I35: =YEARDUR(H35,E35) -> 0 | J35: 70 | K35: 5 | L35: Sports | M35: Exclusive | R35: =IF(S35="","TBD",IF(S35>TODAY(),"Coming Soon",IF(F35="","Active",IF(F35>TODAY(),"Leaving Soon","Removed")))) -> Active | S35: =E35 -> 46217 | T35: =MONTHDUR(E35,S35) -> 0
A36: Ascend to Zero | B36: Xbox / PC | C36: Yes | D36: =IF(E36>TODAY(),"Coming Soon",IF(F36="","Active",IF(F36>TODAY(),"Leaving Soon","Removed"))) -> Active | E36: 46216 | G36: =MONTHDUR(E36,F36) -> 2.7666667 | H36: 46216 | I36: =YEARDUR(H36,E36) -> 0 | J36: 82 | K36: 13 | L36: Action-Adventure | M36: Exclusive | N36: Handheld Optimized | R36: =IF(S36="","TBD",IF(S36>TODAY(),"Coming Soon",IF(F36="","Active",IF(F36>TODAY(),"Leaving Soon","Removed")))) -> TBD | T36: =MONTHDUR(E36,S36) -> 2.7666667
A37: Tamashika | B37: Xbox / PC | C37: Yes | D37: =IF(E37>TODAY(),"Coming Soon",IF(F37="","Active",IF(F37>TODAY(),"Leaving Soon","Removed"))) -> Active | E37: 46212 | G37: =MONTHDUR(E37,F37) -> 2.9 | H37: 46122 | I37: =YEARDUR(H37,E37) -> 0.24722222 | J37: 79 | K37: 2 | L37: Shooter | M37: Exclusive | N37: Handheld Optimized | R37: =IF(S37="","TBD",IF(S37>TODAY(),"Coming Soon",IF(F37="","Active",IF(F37>TODAY(),"Leaving Soon","Removed")))) -> Active | S37: =E37 -> 46212 | T37: =MONTHDUR(E37,S37) -> 0
A38: Buckshot Roulette | B38: Xbox / PC | C38: Yes | D38: =IF(E38>TODAY(),"Coming Soon",IF(F38="","Active",IF(F38>TODAY(),"Leaving Soon","Removed"))) -> Active | E38: 46211 | G38: =MONTHDUR(E38,F38) -> 2.9333333 | H38: 45288 | I38: =YEARDUR(H38,E38) -> 2.5277778 | J38: 85 | K38: 1 | L38: Strategy | R38: =IF(S38="","TBD",IF(S38>TODAY(),"Coming Soon",IF(F38="","Active",IF(F38>TODAY(),"Leaving Soon","Removed")))) -> Active | S38: =E38 -> 46211 | T38: =MONTHDUR(E38,S38) -> 0
A39: Winds of Arcana: Ruination | B39: Xbox / PC | C39: Yes | D39: =IF(E39>TODAY(),"Coming Soon",IF(F39="","Active",IF(F39>TODAY(),"Leaving Soon","Removed"))) -> Active | E39: 46209 | G39: =MONTHDUR(E39,F39) -> 3 | H39: 45975 | I39: =YEARDUR(H39,E39) -> 0.64444444 | J39: 72 | K39: 9 | L39: RPG | N39: Handheld Optimized | R39: =IF(S39="","TBD",IF(S39>TODAY(),"Coming Soon",IF(F39="","Active",IF(F39>TODAY(),"Leaving Soon","Removed")))) -> Active | S39: =E39 -> 46209 | T39: =MONTHDUR(E39,S39) -> 0
A40: RV There Yet? | B40: Xbox / PC | C40: Yes | D40: =IF(E40>TODAY(),"Coming Soon",IF(F40="","Active",IF(F40>TODAY(),"Leaving Soon","Removed"))) -> Active | E40: 46203 | G40: =MONTHDUR(E40,F40) -> 3.2 | H40: 46203 | I40: =YEARDUR(H40,E40) -> 0 | J40: 71 | K40: 4 | L40: Action-Adventure | M40: Exclusive | R40: =IF(S40="","TBD",IF(S40>TODAY(),"Coming Soon",IF(F40="","Active",IF(F40>TODAY(),"Leaving Soon","Removed")))) -> Active | S40: =E40 -> 46203 | T40: =MONTHDUR(E40,S40) -> 0
...

Sheet Likely Leaving
A1: Complete Game Pass Master List by u/ABattleVet | B1: =COUNTIF(D2:D544,"Active")+COUNTIF(D2:D544,"Leaving Soon") -> 89 | C1: https://www.trueachievements.com/gamer/Bloomy/blog | Q1: l
A2: Game | B2: System | C2: xCloud | D2: Status | E2: Added | F2: Removed | G2: Months | H2: Release | I2: Age | J2: Metacritic | K2: Completion | L2: Genre (Giantbomb) | M2: Xbox Series X|S | N2: Owner Notes | O2: ESRB | P2: ESRB Content Descriptors | Q2: Public Notes
A3: =IFERROR(__xludf.DUMMYFUNCTION("SORT(FILTER('Master List'!A:Q, 'Master List'!D:D=""Active"", ISNA(MATCH('Master List'!A:A, 'Xbox Game Studios'!A:A, 0)), ISNA(MATCH('Master List'!A:A, 'EA Play'!A:A, 0)), map('Master List'!G:G, lambda(a, if(isnumber(a), (a > 1) * ((mod(a, 12) > 10.5) + (m"&"od(a, 12) < 1)), 0)))),7,1)"),"Clover Pit") -> Clover Pit | B3: =IFERROR(__xludf.DUMMYFUNCTION("""COMPUTED_VALUE"""),"Xbox / PC") -> Xbox / PC | C3: =IFERROR(__xludf.DUMMYFUNCTION("""COMPUTED_VALUE"""),"Yes") -> Yes | D3: =IFERROR(__xludf.DUMMYFUNCTION("""COMPUTED_VALUE"""),"Active") -> Active | E3: =IFERROR(__xludf.DUMMYFUNCTION("""COMPUTED_VALUE"""),45981.0) -> 45981 | G3: =IFERROR(__xludf.DUMMYFUNCTION("""COMPUTED_VALUE"""),10.533333333333333) -> 10.533333 | H3: =IFERROR(__xludf.DUMMYFUNCTION("""COMPUTED_VALUE"""),45926.0) -> 45926 | I3: =IFERROR(__xludf.DUMMYFUNCTION("""COMPUTED_VALUE"""),0.15) -> 0.15 | J3: =IFERROR(__xludf.DUMMYFUNCTION("""COMPUTED_VALUE"""),77.0) -> 77 | K3: =IFERROR(__xludf.DUMMYFUNCTION("""COMPUTED_VALUE"""),8.0) -> 8 | L3: =IFERROR(__xludf.DUMMYFUNCTION("""COMPUTED_VALUE"""),"Action-Adventure") -> Action-Adventure | N3: =IFERROR(__xludf.DUMMYFUNCTION("""COMPUTED_VALUE"""),"Handheld Optimized") -> Handheld Optimized
A4: =IFERROR(__xludf.DUMMYFUNCTION("""COMPUTED_VALUE"""),"Monsters are Coming! Rock & Road") -> Monsters are Coming! Rock & Road | B4: =IFERROR(__xludf.DUMMYFUNCTION("""COMPUTED_VALUE"""),"PC") -> PC | D4: =IFERROR(__xludf.DUMMYFUNCTION("""COMPUTED_VALUE"""),"Active") -> Active | E4: =IFERROR(__xludf.DUMMYFUNCTION("""COMPUTED_VALUE"""),45981.0) -> 45981 | G4: =IFERROR(__xludf.DUMMYFUNCTION("""COMPUTED_VALUE"""),10.533333333333333) -> 10.533333 | H4: =IFERROR(__xludf.DUMMYFUNCTION("""COMPUTED_VALUE"""),45981.0) -> 45981 | I4: =IFERROR(__xludf.DUMMYFUNCTION("""COMPUTED_VALUE"""),0.0) -> 0 | J4: =IFERROR(__xludf.DUMMYFUNCTION("""COMPUTED_VALUE"""),79.0) -> 79 | K4: =IFERROR(__xludf.DUMMYFUNCTION("""COMPUTED_VALUE"""),3.0) -> 3 | L4: =IFERROR(__xludf.DUMMYFUNCTION("""COMPUTED_VALUE"""),"Action-Adventure") -> Action-Adventure
A5: =IFERROR(__xludf.DUMMYFUNCTION("""COMPUTED_VALUE"""),"The Crew Motorfest") -> The Crew Motorfest | B5: =IFERROR(__xludf.DUMMYFUNCTION("""COMPUTED_VALUE"""),"Xbox / PC") -> Xbox / PC | C5: =IFERROR(__xludf.DUMMYFUNCTION("""COMPUTED_VALUE"""),"Yes") -> Yes | D5: =IFERROR(__xludf.DUMMYFUNCTION("""COMPUTED_VALUE"""),"Active") -> Active | E5: =IFERROR(__xludf.DUMMYFUNCTION("""COMPUTED_VALUE"""),45981.0) -> 45981 | G5: =IFERROR(__xludf.DUMMYFUNCTION("""COMPUTED_VALUE"""),10.533333333333333) -> 10.533333 | H5: =IFERROR(__xludf.DUMMYFUNCTION("""COMPUTED_VALUE"""),45183.0) -> 45183 | I5: =IFERROR(__xludf.DUMMYFUNCTION("""COMPUTED_VALUE"""),2.183333333333333) -> 2.1833333 | J5: =IFERROR(__xludf.DUMMYFUNCTION("""COMPUTED_VALUE"""),76.0) -> 76 | K5: =IFERROR(__xludf.DUMMYFUNCTION("""COMPUTED_VALUE"""),21.0) -> 21 | L5: =IFERROR(__xludf.DUMMYFUNCTION("""COMPUTED_VALUE"""),"Racing") -> Racing
A6: =IFERROR(__xludf.DUMMYFUNCTION("""COMPUTED_VALUE"""),"Total Chaos (2025)") -> Total Chaos (2025) | B6: =IFERROR(__xludf.DUMMYFUNCTION("""COMPUTED_VALUE"""),"Xbox / PC") -> Xbox / PC | C6: =IFERROR(__xludf.DUMMYFUNCTION("""COMPUTED_VALUE"""),"Yes") -> Yes | D6: =IFERROR(__xludf.DUMMYFUNCTION("""COMPUTED_VALUE"""),"Active") -> Active | E6: =IFERROR(__xludf.DUMMYFUNCTION("""COMPUTED_VALUE"""),45981.0) -> 45981 | G6: =IFERROR(__xludf.DUMMYFUNCTION("""COMPUTED_VALUE"""),10.533333333333333) -> 10.533333 | H6: =IFERROR(__xludf.DUMMYFUNCTION("""COMPUTED_VALUE"""),45981.0) -> 45981 | I6: =IFERROR(__xludf.DUMMYFUNCTION("""COMPUTED_VALUE"""),0.0) -> 0 | J6: =IFERROR(__xludf.DUMMYFUNCTION("""COMPUTED_VALUE"""),80.0) -> 80 | K6: =IFERROR(__xludf.DUMMYFUNCTION("""COMPUTED_VALUE"""),11.0) -> 11 | L6: =IFERROR(__xludf.DUMMYFUNCTION("""COMPUTED_VALUE"""),"Action-Adventure") -> Action-Adventure | M6: =IFERROR(__xludf.DUMMYFUNCTION("""COMPUTED_VALUE"""),"Exclusive") -> Exclusive
A7: =IFERROR(__xludf.DUMMYFUNCTION("""COMPUTED_VALUE"""),"Moonlighter 2: The Endless Vault (Game Preview)") -> Moonlighter 2: The Endless Vault (Game Preview) | B7: =IFERROR(__xludf.DUMMYFUNCTION("""COMPUTED_VALUE"""),"PC") -> PC | D7: =IFERROR(__xludf.DUMMYFUNCTION("""COMPUTED_VALUE"""),"Active") -> Active | E7: =IFERROR(__xludf.DUMMYFUNCTION("""COMPUTED_VALUE"""),45980.0) -> 45980 | G7: =IFERROR(__xludf.DUMMYFUNCTION("""COMPUTED_VALUE"""),10.566666666666666) -> 10.566667 | H7: =IFERROR(__xludf.DUMMYFUNCTION("""COMPUTED_VALUE"""),45980.0) -> 45980 | I7: =IFERROR(__xludf.DUMMYFUNCTION("""COMPUTED_VALUE"""),0.0) -> 0 | K7: =IFERROR(__xludf.DUMMYFUNCTION("""COMPUTED_VALUE"""),13.0) -> 13 | L7: =IFERROR(__xludf.DUMMYFUNCTION("""COMPUTED_VALUE"""),"Action-Adventure") -> Action-Adventure
A8: =IFERROR(__xludf.DUMMYFUNCTION("""COMPUTED_VALUE"""),"Relic Hunters Legend") -> Relic Hunters Legend | B8: =IFERROR(__xludf.DUMMYFUNCTION("""COMPUTED_VALUE"""),"Xbox / PC") -> Xbox / PC | C8: =IFERROR(__xludf.DUMMYFUNCTION("""COMPUTED_VALUE"""),"Yes") -> Yes | D8: =IFERROR(__xludf.DUMMYFUNCTION("""COMPUTED_VALUE"""),"Active") -> Active | E8: =IFERROR(__xludf.DUMMYFUNCTION("""COMPUTED_VALUE"""),45973.0) -> 45973 | G8: =IFERROR(__xludf.DUMMYFUNCTION("""COMPUTED_VALUE"""),10.8) -> 10.8 | H8: =IFERROR(__xludf.DUMMYFUNCTION("""COMPUTED_VALUE"""),45883.0) -> 45883 | I8: =IFERROR(__xludf.DUMMYFUNCTION("""COMPUTED_VALUE"""),0.24444444444444444) -> 0.24444444 | K8: =IFERROR(__xludf.DUMMYFUNCTION("""COMPUTED_VALUE"""),29.0) -> 29 | L8: =IFERROR(__xludf.DUMMYFUNCTION("""COMPUTED_VALUE"""),"Shoot-’Em-Up") -> Shoot-’Em-Up
A9: =IFERROR(__xludf.DUMMYFUNCTION("""COMPUTED_VALUE"""),"Winter Burrow") -> Winter Burrow | B9: =IFERROR(__xludf.DUMMYFUNCTION("""COMPUTED_VALUE"""),"Xbox / PC") -> Xbox / PC | C9: =IFERROR(__xludf.DUMMYFUNCTION("""COMPUTED_VALUE"""),"Yes") -> Yes | D9: =IFERROR(__xludf.DUMMYFUNCTION("""COMPUTED_VALUE"""),"Active") -> Active | E9: =IFERROR(__xludf.DUMMYFUNCTION("""COMPUTED_VALUE"""),45973.0) -> 45973 | G9: =IFERROR(__xludf.DUMMYFUNCTION("""COMPUTED_VALUE"""),10.8) -> 10.8 | H9: =IFERROR(__xludf.DUMMYFUNCTION("""COMPUTED_VALUE"""),45973.0) -> 45973 | I9: =IFERROR(__xludf.DUMMYFUNCTION("""COMPUTED_VALUE"""),0.0) -> 0 | J9: =IFERROR(__xludf.DUMMYFUNCTION("""COMPUTED_VALUE"""),68.0) -> 68 | K9: =IFERROR(__xludf.DUMMYFUNCTION("""COMPUTED_VALUE"""),8.0) -> 8 | L9: =IFERROR(__xludf.DUMMYFUNCTION("""COMPUTED_VALUE"""),"Action-Adventure") -> Action-Adventure
A10: =IFERROR(__xludf.DUMMYFUNCTION("""COMPUTED_VALUE"""),"Great God Grove") -> Great God Grove | B10: =IFERROR(__xludf.DUMMYFUNCTION("""COMPUTED_VALUE"""),"Xbox / PC") -> Xbox / PC | C10: =IFERROR(__xludf.DUMMYFUNCTION("""COMPUTED_VALUE"""),"Yes") -> Yes | D10: =IFERROR(__xludf.DUMMYFUNCTION("""COMPUTED_VALUE"""),"Active") -> Active | E10: =IFERROR(__xludf.DUMMYFUNCTION("""COMPUTED_VALUE"""),45972.0) -> 45972 | G10: =IFERROR(__xludf.DUMMYFUNCTION("""COMPUTED_VALUE"""),10.833333333333334) -> 10.833333 | H10: =IFERROR(__xludf.DUMMYFUNCTION("""COMPUTED_VALUE"""),45611.0) -> 45611 | I10: =IFERROR(__xludf.DUMMYFUNCTION("""COMPUTED_VALUE"""),0.9888888888888889) -> 0.98888889 | J10: =IFERROR(__xludf.DUMMYFUNCTION("""COMPUTED_VALUE"""),81.0) -> 81 | K10: =IFERROR(__xludf.DUMMYFUNCTION("""COMPUTED_VALUE"""),6.0) -> 6 | L10: =IFERROR(__xludf.DUMMYFUNCTION("""COMPUTED_VALUE"""),"Action-Adventure") -> Action-Adventure | M10: =IFERROR(__xludf.DUMMYFUNCTION("""COMPUTED_VALUE"""),"Exclusive") -> Exclusive
A11: =IFERROR(__xludf.DUMMYFUNCTION("""COMPUTED_VALUE"""),"Lara Croft and the Temple of Osiris") -> Lara Croft and the Temple of Osiris | B11: =IFERROR(__xludf.DUMMYFUNCTION("""COMPUTED_VALUE"""),"Xbox / PC") -> Xbox / PC | C11: =IFERROR(__xludf.DUMMYFUNCTION("""COMPUTED_VALUE"""),"Yes") -> Yes | D11: =IFERROR(__xludf.DUMMYFUNCTION("""COMPUTED_VALUE"""),"Active") -> Active | E11: =IFERROR(__xludf.DUMMYFUNCTION("""COMPUTED_VALUE"""),45972.0) -> 45972 | G11: =IFERROR(__xludf.DUMMYFUNCTION("""COMPUTED_VALUE"""),10.833333333333334) -> 10.833333 | H11: =IFERROR(__xludf.DUMMYFUNCTION("""COMPUTED_VALUE"""),41982.0) -> 41982 | I11: =IFERROR(__xludf.DUMMYFUNCTION("""COMPUTED_VALUE"""),10.922222222222222) -> 10.922222 | J11: =IFERROR(__xludf.DUMMYFUNCTION("""COMPUTED_VALUE"""),74.0) -> 74 | K11: =IFERROR(__xludf.DUMMYFUNCTION("""COMPUTED_VALUE"""),5.0) -> 5 | L11: =IFERROR(__xludf.DUMMYFUNCTION("""COMPUTED_VALUE"""),"Action-Adventure") -> Action-Adventure
A12: =IFERROR(__xludf.DUMMYFUNCTION("""COMPUTED_VALUE"""),"Pigeon Simulator") -> Pigeon Simulator | B12: =IFERROR(__xludf.DUMMYFUNCTION("""COMPUTED_VALUE"""),"Xbox / PC") -> Xbox / PC | C12: =IFERROR(__xludf.DUMMYFUNCTION("""COMPUTED_VALUE"""),"Yes") -> Yes | D12: =IFERROR(__xludf.DUMMYFUNCTION("""COMPUTED_VALUE"""),"Active") -> Active | E12: =IFERROR(__xludf.DUMMYFUNCTION("""COMPUTED_VALUE"""),45972.0) -> 45972 | G12: =IFERROR(__xludf.DUMMYFUNCTION("""COMPUTED_VALUE"""),10.833333333333334) -> 10.833333 | H12: =IFERROR(__xludf.DUMMYFUNCTION("""COMPUTED_VALUE"""),45972.0) -> 45972 | I12: =IFERROR(__xludf.DUMMYFUNCTION("""COMPUTED_VALUE"""),0.0) -> 0 | J12: =IFERROR(__xludf.DUMMYFUNCTION("""COMPUTED_VALUE"""),64.0) -> 64 | K12: =IFERROR(__xludf.DUMMYFUNCTION("""COMPUTED_VALUE"""),7.0) -> 7 | L12: =IFERROR(__xludf.DUMMYFUNCTION("""COMPUTED_VALUE"""),"Sandbox") -> Sandbox | M12: =IFERROR(__xludf.DUMMYFUNCTION("""COMPUTED_VALUE"""),"Exclusive") -> Exclusive
A13: =IFERROR(__xludf.DUMMYFUNCTION("""COMPUTED_VALUE"""),"Voidtrain") -> Voidtrain | B13: =IFERROR(__xludf.DUMMYFUNCTION("""COMPUTED_VALUE"""),"Xbox / PC") -> Xbox / PC | C13: =IFERROR(__xludf.DUMMYFUNCTION("""COMPUTED_VALUE"""),"Yes") -> Yes | D13: =IFERROR(__xludf.DUMMYFUNCTION("""COMPUTED_VALUE"""),"Active") -> Active | E13: =IFERROR(__xludf.DUMMYFUNCTION("""COMPUTED_VALUE"""),45968.0) -> 45968 | G13: =IFERROR(__xludf.DUMMYFUNCTION("""COMPUTED_VALUE"""),10.966666666666667) -> 10.966667 | H13: =IFERROR(__xludf.DUMMYFUNCTION("""COMPUTED_VALUE"""),45968.0) -> 45968 | I13: =IFERROR(__xludf.DUMMYFUNCTION("""COMPUTED_VALUE"""),0.0) -> 0 | J13: =IFERROR(__xludf.DUMMYFUNCTION("""COMPUTED_VALUE"""),82.0) -> 82 | K13: =IFERROR(__xludf.DUMMYFUNCTION("""COMPUTED_VALUE"""),19.0) -> 19 | L13: =IFERROR(__xludf.DUMMYFUNCTION("""COMPUTED_VALUE"""),"Shooter") -> Shooter | M13: =IFERROR(__xludf.DUMMYFUNCTION("""COMPUTED_VALUE"""),"Exclusive") -> Exclusive
A14: =IFERROR(__xludf.DUMMYFUNCTION("""COMPUTED_VALUE"""),"Egging On") -> Egging On | B14: =IFERROR(__xludf.DUMMYFUNCTION("""COMPUTED_VALUE"""),"Xbox / PC") -> Xbox / PC | C14: =IFERROR(__xludf.DUMMYFUNCTION("""COMPUTED_VALUE"""),"Yes") -> Yes | D14: =IFERROR(__xludf.DUMMYFUNCTION("""COMPUTED_VALUE"""),"Active") -> Active | E14: =IFERROR(__xludf.DUMMYFUNCTION("""COMPUTED_VALUE"""),45967.0) -> 45967 | G14: =IFERROR(__xludf.DUMMYFUNCTION("""COMPUTED_VALUE"""),11.0) -> 11 | H14: =IFERROR(__xludf.DUMMYFUNCTION("""COMPUTED_VALUE"""),45967.0) -> 45967 | I14: =IFERROR(__xludf.DUMMYFUNCTION("""COMPUTED_VALUE"""),0.0) -> 0 | J14: =IFERROR(__xludf.DUMMYFUNCTION("""COMPUTED_VALUE"""),80.0) -> 80 | K14: =IFERROR(__xludf.DUMMYFUNCTION("""COMPUTED_VALUE"""),8.0) -> 8 | L14: =IFERROR(__xludf.DUMMYFUNCTION("""COMPUTED_VALUE"""),"Platformer") -> Platformer | M14: =IFERROR(__xludf.DUMMYFUNCTION("""COMPUTED_VALUE"""),"Exclusive") -> Exclusive
A15: =IFERROR(__xludf.DUMMYFUNCTION("""COMPUTED_VALUE"""),"Dead Static Drive") -> Dead Static Drive | B15: =IFERROR(__xludf.DUMMYFUNCTION("""COMPUTED_VALUE"""),"Xbox / PC") -> Xbox / PC | C15: =IFERROR(__xludf.DUMMYFUNCTION("""COMPUTED_VALUE"""),"Yes") -> Yes | D15: =IFERROR(__xludf.DUMMYFUNCTION("""COMPUTED_VALUE"""),"Active") -> Active | E15: =IFERROR(__xludf.DUMMYFUNCTION("""COMPUTED_VALUE"""),45966.0) -> 45966 | G15: =IFERROR(__xludf.DUMMYFUNCTION("""COMPUTED_VALUE"""),11.033333333333333) -> 11.033333 | H15: =IFERROR(__xludf.DUMMYFUNCTION("""COMPUTED_VALUE"""),45966.0) -> 45966 | I15: =IFERROR(__xludf.DUMMYFUNCTION("""COMPUTED_VALUE"""),0.0) -> 0 | J15: =IFERROR(__xludf.DUMMYFUNCTION("""COMPUTED_VALUE"""),35.0) -> 35 | K15: =IFERROR(__xludf.DUMMYFUNCTION("""COMPUTED_VALUE"""),4.0) -> 4 | L15: =IFERROR(__xludf.DUMMYFUNCTION("""COMPUTED_VALUE"""),"Survival") -> Survival
A16: =IFERROR(__xludf.DUMMYFUNCTION("""COMPUTED_VALUE"""),"1000xResist") -> 1000xResist | B16: =IFERROR(__xludf.DUMMYFUNCTION("""COMPUTED_VALUE"""),"Xbox / PC") -> Xbox / PC | C16: =IFERROR(__xludf.DUMMYFUNCTION("""COMPUTED_VALUE"""),"Yes") -> Yes | D16: =IFERROR(__xludf.DUMMYFUNCTION("""COMPUTED_VALUE"""),"Active") -> Active | E16: =IFERROR(__xludf.DUMMYFUNCTION("""COMPUTED_VALUE"""),45965.0) -> 45965 | G16: =IFERROR(__xludf.DUMMYFUNCTION("""COMPUTED_VALUE"""),11.066666666666666) -> 11.066667 | H16: =IFERROR(__xludf.DUMMYFUNCTION("""COMPUTED_VALUE"""),45786.0) -> 45786 | I16: =IFERROR(__xludf.DUMMYFUNCTION("""COMPUTED_VALUE"""),0.4861111111111111) -> 0.48611111 | J16: =IFERROR(__xludf.DUMMYFUNCTION("""COMPUTED_VALUE"""),86.0) -> 86 | K16: =IFERROR(__xludf.DUMMYFUNCTION("""COMPUTED_VALUE"""),11.0) -> 11 | L16: =IFERROR(__xludf.DUMMYFUNCTION("""COMPUTED_VALUE"""),"Action-Adventure") -> Action-Adventure | M16: =IFERROR(__xludf.DUMMYFUNCTION("""COMPUTED_VALUE"""),"Exclusive") -> Exclusive
A17: =IFERROR(__xludf.DUMMYFUNCTION("""COMPUTED_VALUE"""),"Football Manager 26") -> Football Manager 26 | B17: =IFERROR(__xludf.DUMMYFUNCTION("""COMPUTED_VALUE"""),"PC") -> PC | D17: =IFERROR(__xludf.DUMMYFUNCTION("""COMPUTED_VALUE"""),"Active") -> Active | E17: =IFERROR(__xludf.DUMMYFUNCTION("""COMPUTED_VALUE"""),45965.0) -> 45965 | G17: =IFERROR(__xludf.DUMMYFUNCTION("""COMPUTED_VALUE"""),11.066666666666666) -> 11.066667 | H17: =IFERROR(__xludf.DUMMYFUNCTION("""COMPUTED_VALUE"""),45965.0) -> 45965 | I17: =IFERROR(__xludf.DUMMYFUNCTION("""COMPUTED_VALUE"""),0.0) -> 0 | J17: =IFERROR(__xludf.DUMMYFUNCTION("""COMPUTED_VALUE"""),68.0) -> 68 | K17: =IFERROR(__xludf.DUMMYFUNCTION("""COMPUTED_VALUE"""),64.0) -> 64 | L17: =IFERROR(__xludf.DUMMYFUNCTION("""COMPUTED_VALUE"""),"Management") -> Management
A18: =IFERROR(__xludf.DUMMYFUNCTION("""COMPUTED_VALUE"""),"Halls of Torment") -> Halls of Torment | B18: =IFERROR(__xludf.DUMMYFUNCTION("""COMPUTED_VALUE"""),"Xbox / PC") -> Xbox / PC | C18: =IFERROR(__xludf.DUMMYFUNCTION("""COMPUTED_VALUE"""),"Yes") -> Yes | D18: =IFERROR(__xludf.DUMMYFUNCTION("""COMPUTED_VALUE"""),"Active") -> Active | E18: =IFERROR(__xludf.DUMMYFUNCTION("""COMPUTED_VALUE"""),45958.0) -> 45958 | G18: =IFERROR(__xludf.DUMMYFUNCTION("""COMPUTED_VALUE"""),11.266666666666666) -> 11.266667 | H18: =IFERROR(__xludf.DUMMYFUNCTION("""COMPUTED_VALUE"""),45559.0) -> 45559 | I18: =IFERROR(__xludf.DUMMYFUNCTION("""COMPUTED_VALUE"""),1.0944444444444446) -> 1.0944444 | J18: =IFERROR(__xludf.DUMMYFUNCTION("""COMPUTED_VALUE"""),88.0) -> 88 | K18: =IFERROR(__xludf.DUMMYFUNCTION("""COMPUTED_VALUE"""),12.0) -> 12 | L18: =IFERROR(__xludf.DUMMYFUNCTION("""COMPUTED_VALUE"""),"Shoot-'Em-Up") -> Shoot-'Em-Up | M18: =IFERROR(__xludf.DUMMYFUNCTION("""COMPUTED_VALUE"""),"Exclusive") -> Exclusive
A19: =IFERROR(__xludf.DUMMYFUNCTION("""COMPUTED_VALUE"""),"PowerWash Simulator 2") -> PowerWash Simulator 2 | B19: =IFERROR(__xludf.DUMMYFUNCTION("""COMPUTED_VALUE"""),"Xbox / PC") -> Xbox / PC | C19: =IFERROR(__xludf.DUMMYFUNCTION("""COMPUTED_VALUE"""),"Yes") -> Yes | D19: =IFERROR(__xludf.DUMMYFUNCTION("""COMPUTED_VALUE"""),"Active") -> Active | E19: =IFERROR(__xludf.DUMMYFUNCTION("""COMPUTED_VALUE"""),45953.0) -> 45953 | G19: =IFERROR(__xludf.DUMMYFUNCTION("""COMPUTED_VALUE"""),11.433333333333334) -> 11.433333 | H19: =IFERROR(__xludf.DUMMYFUNCTION("""COMPUTED_VALUE"""),45953.0) -> 45953 | I19: =IFERROR(__xludf.DUMMYFUNCTION("""COMPUTED_VALUE"""),0.0) -> 0 | J19: =IFERROR(__xludf.DUMMYFUNCTION("""COMPUTED_VALUE"""),82.0) -> 82 | K19: =IFERROR(__xludf.DUMMYFUNCTION("""COMPUTED_VALUE"""),37.0) -> 37 | L19: =IFERROR(__xludf.DUMMYFUNCTION("""COMPUTED_VALUE"""),"Simulation") -> Simulation | M19: =IFERROR(__xludf.DUMMYFUNCTION("""COMPUTED_VALUE"""),"Exclusive") -> Exclusive
A20: =IFERROR(__xludf.DUMMYFUNCTION("""COMPUTED_VALUE"""),"Bounty Star: The Morose Tale of Graveyard Clem") -> Bounty Star: The Morose Tale of Graveyard Clem | B20: =IFERROR(__xludf.DUMMYFUNCTION("""COMPUTED_VALUE"""),"Xbox / PC") -> Xbox / PC | C20: =IFERROR(__xludf.DUMMYFUNCTION("""COMPUTED_VALUE"""),"Yes") -> Yes | D20: =IFERROR(__xludf.DUMMYFUNCTION("""COMPUTED_VALUE"""),"Active") -> Active | E20: =IFERROR(__xludf.DUMMYFUNCTION("""COMPUTED_VALUE"""),45953.0) -> 45953 | G20: =IFERROR(__xludf.DUMMYFUNCTION("""COMPUTED_VALUE"""),11.433333333333334) -> 11.433333 | H20: =IFERROR(__xludf.DUMMYFUNCTION("""COMPUTED_VALUE"""),45953.0) -> 45953 | I20: =IFERROR(__xludf.DUMMYFUNCTION("""COMPUTED_VALUE"""),0.0) -> 0 | J20: =IFERROR(__xludf.DUMMYFUNCTION("""COMPUTED_VALUE"""),74.0) -> 74 | K20: =IFERROR(__xludf.DUMMYFUNCTION("""COMPUTED_VALUE"""),13.0) -> 13 | L20: =IFERROR(__xludf.DUMMYFUNCTION("""COMPUTED_VALUE"""),"Shooter") -> Shooter | M20: =IFERROR(__xludf.DUMMYFUNCTION("""COMPUTED_VALUE"""),"Exclusive") -> Exclusive
A21: =IFERROR(__xludf.DUMMYFUNCTION("""COMPUTED_VALUE"""),"Keeper (2025)") -> Keeper (2025) | B21: =IFERROR(__xludf.DUMMYFUNCTION("""COMPUTED_VALUE"""),"Xbox / PC") -> Xbox / PC | C21: =IFERROR(__xludf.DUMMYFUNCTION("""COMPUTED_VALUE"""),"Yes") -> Yes | D21: =IFERROR(__xludf.DUMMYFUNCTION("""COMPUTED_VALUE"""),"Active") -> Active | E21: =IFERROR(__xludf.DUMMYFUNCTION("""COMPUTED_VALUE"""),45947.0) -> 45947 | G21: =IFERROR(__xludf.DUMMYFUNCTION("""COMPUTED_VALUE"""),11.633333333333333) -> 11.633333 | H21: =IFERROR(__xludf.DUMMYFUNCTION("""COMPUTED_VALUE"""),45947.0) -> 45947 | I21: =IFERROR(__xludf.DUMMYFUNCTION("""COMPUTED_VALUE"""),0.0) -> 0 | J21: =IFERROR(__xludf.DUMMYFUNCTION("""COMPUTED_VALUE"""),80.0) -> 80 | K21: =IFERROR(__xludf.DUMMYFUNCTION("""COMPUTED_VALUE"""),5.0) -> 5 | L21: =IFERROR(__xludf.DUMMYFUNCTION("""COMPUTED_VALUE"""),"Action-Adventure") -> Action-Adventure | M21: =IFERROR(__xludf.DUMMYFUNCTION("""COMPUTED_VALUE"""),"Exclusive") -> Exclusive
A22: =IFERROR(__xludf.DUMMYFUNCTION("""COMPUTED_VALUE"""),"Pax Dei") -> Pax Dei | B22: =IFERROR(__xludf.DUMMYFUNCTION("""COMPUTED_VALUE"""),"PC") -> PC | D22: =IFERROR(__xludf.DUMMYFUNCTION("""COMPUTED_VALUE"""),"Active") -> Active | E22: =IFERROR(__xludf.DUMMYFUNCTION("""COMPUTED_VALUE"""),45946.0) -> 45946 | G22: =IFERROR(__xludf.DUMMYFUNCTION("""COMPUTED_VALUE"""),11.666666666666666) -> 11.666667 | H22: =IFERROR(__xludf.DUMMYFUNCTION("""COMPUTED_VALUE"""),45946.0) -> 45946 | I22: =IFERROR(__xludf.DUMMYFUNCTION("""COMPUTED_VALUE"""),0.0) -> 0 | J22: =IFERROR(__xludf.DUMMYFUNCTION("""COMPUTED_VALUE"""),70.0) -> 70 | L22: =IFERROR(__xludf.DUMMYFUNCTION("""COMPUTED_VALUE"""),"RPG") -> RPG
A23: =IFERROR(__xludf.DUMMYFUNCTION("""COMPUTED_VALUE"""),"Ball x Pit") -> Ball x Pit | B23: =IFERROR(__xludf.DUMMYFUNCTION("""COMPUTED_VALUE"""),"Xbox / PC") -> Xbox / PC | C23: =IFERROR(__xludf.DUMMYFUNCTION("""COMPUTED_VALUE"""),"Yes") -> Yes | D23: =IFERROR(__xludf.DUMMYFUNCTION("""COMPUTED_VALUE"""),"Active") -> Active | E23: =IFERROR(__xludf.DUMMYFUNCTION("""COMPUTED_VALUE"""),45945.0) -> 45945 | G23: =IFERROR(__xludf.DUMMYFUNCTION("""COMPUTED_VALUE"""),11.7) -> 11.7 | H23: =IFERROR(__xludf.DUMMYFUNCTION("""COMPUTED_VALUE"""),45945.0) -> 45945 | I23: =IFERROR(__xludf.DUMMYFUNCTION("""COMPUTED_VALUE"""),0.0) -> 0 | J23: =IFERROR(__xludf.DUMMYFUNCTION("""COMPUTED_VALUE"""),84.0) -> 84 | K23: =IFERROR(__xludf.DUMMYFUNCTION("""COMPUTED_VALUE"""),19.0) -> 19 | L23: =IFERROR(__xludf.DUMMYFUNCTION("""COMPUTED_VALUE"""),"Shoot-'Em-Up") -> Shoot-'Em-Up
A24: =IFERROR(__xludf.DUMMYFUNCTION("""COMPUTED_VALUE"""),"Heroes of Might and Magic II: Gold Edition") -> Heroes of Might and Magic II: Gold Edition | B24: =IFERROR(__xludf.DUMMYFUNCTION("""COMPUTED_VALUE"""),"PC") -> PC | D24: =IFERROR(__xludf.DUMMYFUNCTION("""COMPUTED_VALUE"""),"Active") -> Active | E24: =IFERROR(__xludf.DUMMYFUNCTION("""COMPUTED_VALUE"""),45940.0) -> 45940 | G24: =IFERROR(__xludf.DUMMYFUNCTION("""COMPUTED_VALUE"""),11.866666666666667) -> 11.866667 | H24: =IFERROR(__xludf.DUMMYFUNCTION("""COMPUTED_VALUE"""),35338.0) -> 35338 | I24: =IFERROR(__xludf.DUMMYFUNCTION("""COMPUTED_VALUE"""),29.02777777777778) -> 29.027778 | J24: =IFERROR(__xludf.DUMMYFUNCTION("""COMPUTED_VALUE"""),84.0) -> 84 | K24: =IFERROR(__xludf.DUMMYFUNCTION("""COMPUTED_VALUE"""),80.0) -> 80 | L24: =IFERROR(__xludf.DUMMYFUNCTION("""COMPUTED_VALUE"""),"Strategy") -> Strategy | N24: =IFERROR(__xludf.DUMMYFUNCTION("""COMPUTED_VALUE"""),"Ubisoft games joining with price increase") -> Ubisoft games joining with price increase
A25: =IFERROR(__xludf.DUMMYFUNCTION("""COMPUTED_VALUE"""),"Heroes of Might and Magic III: Complete Edition") -> Heroes of Might and Magic III: Complete Edition | B25: =IFERROR(__xludf.DUMMYFUNCTION("""COMPUTED_VALUE"""),"PC") -> PC | D25: =IFERROR(__xludf.DUMMYFUNCTION("""COMPUTED_VALUE"""),"Active") -> Active | E25: =IFERROR(__xludf.DUMMYFUNCTION("""COMPUTED_VALUE"""),45940.0) -> 45940 | G25: =IFERROR(__xludf.DUMMYFUNCTION("""COMPUTED_VALUE"""),11.866666666666667) -> 11.866667 | H25: =IFERROR(__xludf.DUMMYFUNCTION("""COMPUTED_VALUE"""),36219.0) -> 36219 | I25: =IFERROR(__xludf.DUMMYFUNCTION("""COMPUTED_VALUE"""),26.616666666666667) -> 26.616667 | J25: =IFERROR(__xludf.DUMMYFUNCTION("""COMPUTED_VALUE"""),65.0) -> 65 | K25: =IFERROR(__xludf.DUMMYFUNCTION("""COMPUTED_VALUE"""),153.0) -> 153 | L25: =IFERROR(__xludf.DUMMYFUNCTION("""COMPUTED_VALUE"""),"Strategy") -> Strategy | N25: =IFERROR(__xludf.DUMMYFUNCTION("""COMPUTED_VALUE"""),"Ubisoft games joining with price increase") -> Ubisoft games joining with price increase
A26: =IFERROR(__xludf.DUMMYFUNCTION("""COMPUTED_VALUE"""),"Supermarket Simulator") -> Supermarket Simulator | B26: =IFERROR(__xludf.DUMMYFUNCTION("""COMPUTED_VALUE"""),"Xbox / PC") -> Xbox / PC | C26: =IFERROR(__xludf.DUMMYFUNCTION("""COMPUTED_VALUE"""),"Yes") -> Yes | D26: =IFERROR(__xludf.DUMMYFUNCTION("""COMPUTED_VALUE"""),"Active") -> Active | E26: =IFERROR(__xludf.DUMMYFUNCTION("""COMPUTED_VALUE"""),45938.0) -> 45938 | G26: =IFERROR(__xludf.DUMMYFUNCTION("""COMPUTED_VALUE"""),11.933333333333334) -> 11.933333 | H26: =IFERROR(__xludf.DUMMYFUNCTION("""COMPUTED_VALUE"""),45827.0) -> 45827 | I26: =IFERROR(__xludf.DUMMYFUNCTION("""COMPUTED_VALUE"""),0.30277777777777776) -> 0.30277778 | J26: =IFERROR(__xludf.DUMMYFUNCTION("""COMPUTED_VALUE"""),76.66666666666667) -> 76.666667 | K26: =IFERROR(__xludf.DUMMYFUNCTION("""COMPUTED_VALUE"""),22.0) -> 22 | L26: =IFERROR(__xludf.DUMMYFUNCTION("""COMPUTED_VALUE"""),"Simulation") -> Simulation
A27: =IFERROR(__xludf.DUMMYFUNCTION("""COMPUTED_VALUE"""),"Hogwarts Legacy") -> Hogwarts Legacy | B27: =IFERROR(__xludf.DUMMYFUNCTION("""COMPUTED_VALUE"""),"Xbox / PC") -> Xbox / PC | C27: =IFERROR(__xludf.DUMMYFUNCTION("""COMPUTED_VALUE"""),"Yes") -> Yes | D27: =IFERROR(__xludf.DUMMYFUNCTION("""COMPUTED_VALUE"""),"Active") -> Active | E27: =IFERROR(__xludf.DUMMYFUNCTION("""COMPUTED_VALUE"""),45931.0) -> 45931 | G27: =IFERROR(__xludf.DUMMYFUNCTION("""COMPUTED_VALUE"""),12.166666666666666) -> 12.166667 | H27: =IFERROR(__xludf.DUMMYFUNCTION("""COMPUTED_VALUE"""),44964.0) -> 44964 | I27: =IFERROR(__xludf.DUMMYFUNCTION("""COMPUTED_VALUE"""),2.65) -> 2.65 | J27: =IFERROR(__xludf.DUMMYFUNCTION("""COMPUTED_VALUE"""),84.0) -> 84 | K27: =IFERROR(__xludf.DUMMYFUNCTION("""COMPUTED_VALUE"""),27.0) -> 27 | L27: =IFERROR(__xludf.DUMMYFUNCTION("""COMPUTED_VALUE"""),"Action-Adventure") -> Action-Adventure | N27: =IFERROR(__xludf.DUMMYFUNCTION("""COMPUTED_VALUE"""),"Ubisoft games joining with price increase") -> Ubisoft games joining with price increase
A28: =IFERROR(__xludf.DUMMYFUNCTION("""COMPUTED_VALUE"""),"Assassin's Creed II") -> Assassin's Creed II | B28: =IFERROR(__xludf.DUMMYFUNCTION("""COMPUTED_VALUE"""),"Xbox / PC") -> Xbox / PC | D28: =IFERROR(__xludf.DUMMYFUNCTION("""COMPUTED_VALUE"""),"Active") -> Active | E28: =IFERROR(__xludf.DUMMYFUNCTION("""COMPUTED_VALUE"""),45931.0) -> 45931 | G28: =IFERROR(__xludf.DUMMYFUNCTION("""COMPUTED_VALUE"""),12.166666666666666) -> 12.166667 | H28: =IFERROR(__xludf.DUMMYFUNCTION("""COMPUTED_VALUE"""),40134.0) -> 40134 | I28: =IFERROR(__xludf.DUMMYFUNCTION("""COMPUTED_VALUE"""),15.872222222222222) -> 15.872222 | J28: =IFERROR(__xludf.DUMMYFUNCTION("""COMPUTED_VALUE"""),90.0) -> 90 | K28: =IFERROR(__xludf.DUMMYFUNCTION("""COMPUTED_VALUE"""),19.0) -> 19 | L28: =IFERROR(__xludf.DUMMYFUNCTION("""COMPUTED_VALUE"""),"Action-Adventure") -> Action-Adventure | N28: =IFERROR(__xludf.DUMMYFUNCTION("""COMPUTED_VALUE"""),"Ubisoft games joining with price increase") -> Ubisoft games joining with price increase
A29: =IFERROR(__xludf.DUMMYFUNCTION("""COMPUTED_VALUE"""),"Assassin's Creed III: Remastered") -> Assassin's Creed III: Remastered | B29: =IFERROR(__xludf.DUMMYFUNCTION("""COMPUTED_VALUE"""),"Xbox / PC") -> Xbox / PC | C29: =IFERROR(__xludf.DUMMYFUNCTION("""COMPUTED_VALUE"""),"Yes") -> Yes | D29: =IFERROR(__xludf.DUMMYFUNCTION("""COMPUTED_VALUE"""),"Active") -> Active | E29: =IFERROR(__xludf.DUMMYFUNCTION("""COMPUTED_VALUE"""),45931.0) -> 45931 | G29: =IFERROR(__xludf.DUMMYFUNCTION("""COMPUTED_VALUE"""),12.166666666666666) -> 12.166667 | H29: =IFERROR(__xludf.DUMMYFUNCTION("""COMPUTED_VALUE"""),43553.0) -> 43553 | I29: =IFERROR(__xludf.DUMMYFUNCTION("""COMPUTED_VALUE"""),6.5055555555555555) -> 6.5055556 | J29: =IFERROR(__xludf.DUMMYFUNCTION("""COMPUTED_VALUE"""),72.0) -> 72 | K29: =IFERROR(__xludf.DUMMYFUNCTION("""COMPUTED_VALUE"""),15.0) -> 15 | L29: =IFERROR(__xludf.DUMMYFUNCTION("""COMPUTED_VALUE"""),"Action-Adventure") -> Action-Adventure | N29: =IFERROR(__xludf.DUMMYFUNCTION("""COMPUTED_VALUE"""),"Ubisoft games joining with price increase") -> Ubisoft games joining with price increase
A30: =IFERROR(__xludf.DUMMYFUNCTION("""COMPUTED_VALUE"""),"Assassin's Creed IV Black Flag") -> Assassin's Creed IV Black Flag | B30: =IFERROR(__xludf.DUMMYFUNCTION("""COMPUTED_VALUE"""),"Xbox / PC") -> Xbox / PC | C30: =IFERROR(__xludf.DUMMYFUNCTION("""COMPUTED_VALUE"""),"Yes") -> Yes | D30: =IFERROR(__xludf.DUMMYFUNCTION("""COMPUTED_VALUE"""),"Active") -> Active | E30: =IFERROR(__xludf.DUMMYFUNCTION("""COMPUTED_VALUE"""),45931.0) -> 45931 | G30: =IFERROR(__xludf.DUMMYFUNCTION("""COMPUTED_VALUE"""),12.166666666666666) -> 12.166667 | H30: =IFERROR(__xludf.DUMMYFUNCTION("""COMPUTED_VALUE"""),41576.0) -> 41576 | I30: =IFERROR(__xludf.DUMMYFUNCTION("""COMPUTED_VALUE"""),11.922222222222222) -> 11.922222 | J30: =IFERROR(__xludf.DUMMYFUNCTION("""COMPUTED_VALUE"""),88.0) -> 88 | K30: =IFERROR(__xludf.DUMMYFUNCTION("""COMPUTED_VALUE"""),24.0) -> 24 | L30: =IFERROR(__xludf.DUMMYFUNCTION("""COMPUTED_VALUE"""),"Action-Adventure") -> Action-Adventure | N30: =IFERROR(__xludf.DUMMYFUNCTION("""COMPUTED_VALUE"""),"Ubisoft games joining with price increase") -> Ubisoft games joining with price increase
A31: =IFERROR(__xludf.DUMMYFUNCTION("""COMPUTED_VALUE"""),"Assassin's Creed IV Black Flag: Freedom Cry") -> Assassin's Creed IV Black Flag: Freedom Cry | B31: =IFERROR(__xludf.DUMMYFUNCTION("""COMPUTED_VALUE"""),"Xbox / PC") -> Xbox / PC | D31: =IFERROR(__xludf.DUMMYFUNCTION("""COMPUTED_VALUE"""),"Active") -> Active | E31: =IFERROR(__xludf.DUMMYFUNCTION("""COMPUTED_VALUE"""),45931.0) -> 45931 | G31: =IFERROR(__xludf.DUMMYFUNCTION("""COMPUTED_VALUE"""),12.166666666666666) -> 12.166667 | H31: =IFERROR(__xludf.DUMMYFUNCTION("""COMPUTED_VALUE"""),41626.0) -> 41626 | I31: =IFERROR(__xludf.DUMMYFUNCTION("""COMPUTED_VALUE"""),11.786111111111111) -> 11.786111 | J31: =IFERROR(__xludf.DUMMYFUNCTION("""COMPUTED_VALUE"""),71.0) -> 71 | K31: =IFERROR(__xludf.DUMMYFUNCTION("""COMPUTED_VALUE"""),4.0) -> 4 | L31: =IFERROR(__xludf.DUMMYFUNCTION("""COMPUTED_VALUE"""),"Action-Adventure") -> Action-Adventure | N31: =IFERROR(__xludf.DUMMYFUNCTION("""COMPUTED_VALUE"""),"Ubisoft games joining with price increase") -> Ubisoft games joining with price increase
A32: =IFERROR(__xludf.DUMMYFUNCTION("""COMPUTED_VALUE"""),"Assassin's Creed Brotherhood") -> Assassin's Creed Brotherhood | B32: =IFERROR(__xludf.DUMMYFUNCTION("""COMPUTED_VALUE"""),"Xbox / PC") -> Xbox / PC | D32: =IFERROR(__xludf.DUMMYFUNCTION("""COMPUTED_VALUE"""),"Active") -> Active | E32: =IFERROR(__xludf.DUMMYFUNCTION("""COMPUTED_VALUE"""),45931.0) -> 45931 | G32: =IFERROR(__xludf.DUMMYFUNCTION("""COMPUTED_VALUE"""),12.166666666666666) -> 12.166667 | H32: =IFERROR(__xludf.DUMMYFUNCTION("""COMPUTED_VALUE"""),40498.0) -> 40498 | I32: =IFERROR(__xludf.DUMMYFUNCTION("""COMPUTED_VALUE"""),14.875) -> 14.875 | J32: =IFERROR(__xludf.DUMMYFUNCTION("""COMPUTED_VALUE"""),89.0) -> 89 | K32: =IFERROR(__xludf.DUMMYFUNCTION("""COMPUTED_VALUE"""),15.0) -> 15 | L32: =IFERROR(__xludf.DUMMYFUNCTION("""COMPUTED_VALUE"""),"Action-Adventure") -> Action-Adventure | N32: =IFERROR(__xludf.DUMMYFUNCTION("""COMPUTED_VALUE"""),"Ubisoft games joining with price increase") -> Ubisoft games joining with price increase
A33: =IFERROR(__xludf.DUMMYFUNCTION("""COMPUTED_VALUE"""),"Assassin's Creed Chronicles: China") -> Assassin's Creed Chronicles: China | B33: =IFERROR(__xludf.DUMMYFUNCTION("""COMPUTED_VALUE"""),"Xbox / PC") -> Xbox / PC | C33: =IFERROR(__xludf.DUMMYFUNCTION("""COMPUTED_VALUE"""),"Yes") -> Yes | D33: =IFERROR(__xludf.DUMMYFUNCTION("""COMPUTED_VALUE"""),"Active") -> Active | E33: =IFERROR(__xludf.DUMMYFUNCTION("""COMPUTED_VALUE"""),45931.0) -> 45931 | G33: =IFERROR(__xludf.DUMMYFUNCTION("""COMPUTED_VALUE"""),12.166666666666666) -> 12.166667 | H33: =IFERROR(__xludf.DUMMYFUNCTION("""COMPUTED_VALUE"""),42115.0) -> 42115 | I33: =IFERROR(__xludf.DUMMYFUNCTION("""COMPUTED_VALUE"""),10.444444444444445) -> 10.444444 | J33: =IFERROR(__xludf.DUMMYFUNCTION("""COMPUTED_VALUE"""),69.0) -> 69 | K33: =IFERROR(__xludf.DUMMYFUNCTION("""COMPUTED_VALUE"""),6.0) -> 6 | L33: =IFERROR(__xludf.DUMMYFUNCTION("""COMPUTED_VALUE"""),"Action-Adventure") -> Action-Adventure | N33: =IFERROR(__xludf.DUMMYFUNCTION("""COMPUTED_VALUE"""),"Ubisoft games joining with price increase") -> Ubisoft games joining with price increase
A34: =IFERROR(__xludf.DUMMYFUNCTION("""COMPUTED_VALUE"""),"Assassin's Creed Chronicles: India") -> Assassin's Creed Chronicles: India | B34: =IFERROR(__xludf.DUMMYFUNCTION("""COMPUTED_VALUE"""),"Xbox / PC") -> Xbox / PC | C34: =IFERROR(__xludf.DUMMYFUNCTION("""COMPUTED_VALUE"""),"Yes") -> Yes | D34: =IFERROR(__xludf.DUMMYFUNCTION("""COMPUTED_VALUE"""),"Active") -> Active | E34: =IFERROR(__xludf.DUMMYFUNCTION("""COMPUTED_VALUE"""),45931.0) -> 45931 | G34: =IFERROR(__xludf.DUMMYFUNCTION("""COMPUTED_VALUE"""),12.166666666666666) -> 12.166667 | H34: =IFERROR(__xludf.DUMMYFUNCTION("""COMPUTED_VALUE"""),42382.0) -> 42382 | I34: =IFERROR(__xludf.DUMMYFUNCTION("""COMPUTED_VALUE"""),9.716666666666667) -> 9.7166667 | J34: =IFERROR(__xludf.DUMMYFUNCTION("""COMPUTED_VALUE"""),63.0) -> 63 | K34: =IFERROR(__xludf.DUMMYFUNCTION("""COMPUTED_VALUE"""),6.0) -> 6 | L34: =IFERROR(__xludf.DUMMYFUNCTION("""COMPUTED_VALUE"""),"Action-Adventure") -> Action-Adventure | N34: =IFERROR(__xludf.DUMMYFUNCTION("""COMPUTED_VALUE"""),"Ubisoft games joining with price increase") -> Ubisoft games joining with price increase
A35: =IFERROR(__xludf.DUMMYFUNCTION("""COMPUTED_VALUE"""),"Assassin's Creed Chronicles: Russia") -> Assassin's Creed Chronicles: Russia | B35: =IFERROR(__xludf.DUMMYFUNCTION("""COMPUTED_VALUE"""),"Xbox / PC") -> Xbox / PC | C35: =IFERROR(__xludf.DUMMYFUNCTION("""COMPUTED_VALUE"""),"Yes") -> Yes | D35: =IFERROR(__xludf.DUMMYFUNCTION("""COMPUTED_VALUE"""),"Active") -> Active | E35: =IFERROR(__xludf.DUMMYFUNCTION("""COMPUTED_VALUE"""),45931.0) -> 45931 | G35: =IFERROR(__xludf.DUMMYFUNCTION("""COMPUTED_VALUE"""),12.166666666666666) -> 12.166667 | H35: =IFERROR(__xludf.DUMMYFUNCTION("""COMPUTED_VALUE"""),42409.0) -> 42409 | I35: =IFERROR(__xludf.DUMMYFUNCTION("""COMPUTED_VALUE"""),9.644444444444444) -> 9.6444444 | J35: =IFERROR(__xludf.DUMMYFUNCTION("""COMPUTED_VALUE"""),62.0) -> 62 | K35: =IFERROR(__xludf.DUMMYFUNCTION("""COMPUTED_VALUE"""),7.0) -> 7 | L35: =IFERROR(__xludf.DUMMYFUNCTION("""COMPUTED_VALUE"""),"Action-Adventure") -> Action-Adventure | N35: =IFERROR(__xludf.DUMMYFUNCTION("""COMPUTED_VALUE"""),"Ubisoft games joining with price increase") -> Ubisoft games joining with price increase
A36: =IFERROR(__xludf.DUMMYFUNCTION("""COMPUTED_VALUE"""),"Assassin's Creed Liberation HD") -> Assassin's Creed Liberation HD | B36: =IFERROR(__xludf.DUMMYFUNCTION("""COMPUTED_VALUE"""),"Xbox / PC") -> Xbox / PC | D36: =IFERROR(__xludf.DUMMYFUNCTION("""COMPUTED_VALUE"""),"Active") -> Active | E36: =IFERROR(__xludf.DUMMYFUNCTION("""COMPUTED_VALUE"""),45931.0) -> 45931 | G36: =IFERROR(__xludf.DUMMYFUNCTION("""COMPUTED_VALUE"""),12.166666666666666) -> 12.166667 | H36: =IFERROR(__xludf.DUMMYFUNCTION("""COMPUTED_VALUE"""),41654.0) -> 41654 | I36: =IFERROR(__xludf.DUMMYFUNCTION("""COMPUTED_VALUE"""),11.71111111111111) -> 11.711111 | J36: =IFERROR(__xludf.DUMMYFUNCTION("""COMPUTED_VALUE"""),62.0) -> 62 | K36: =IFERROR(__xludf.DUMMYFUNCTION("""COMPUTED_VALUE"""),8.0) -> 8 | L36: =IFERROR(__xludf.DUMMYFUNCTION("""COMPUTED_VALUE"""),"Action-Adventure") -> Action-Adventure | N36: =IFERROR(__xludf.DUMMYFUNCTION("""COMPUTED_VALUE"""),"Ubisoft games joining with price increase") -> Ubisoft games joining with price increase
A37: =IFERROR(__xludf.DUMMYFUNCTION("""COMPUTED_VALUE"""),"Assassin's Creed Revelations") -> Assassin's Creed Revelations | B37: =IFERROR(__xludf.DUMMYFUNCTION("""COMPUTED_VALUE"""),"Xbox / PC") -> Xbox / PC | D37: =IFERROR(__xludf.DUMMYFUNCTION("""COMPUTED_VALUE"""),"Active") -> Active | E37: =IFERROR(__xludf.DUMMYFUNCTION("""COMPUTED_VALUE"""),45931.0) -> 45931 | G37: =IFERROR(__xludf.DUMMYFUNCTION("""COMPUTED_VALUE"""),12.166666666666666) -> 12.166667 | H37: =IFERROR(__xludf.DUMMYFUNCTION("""COMPUTED_VALUE"""),40862.0) -> 40862 | I37: =IFERROR(__xludf.DUMMYFUNCTION("""COMPUTED_VALUE"""),13.877777777777778) -> 13.877778 | J37: =IFERROR(__xludf.DUMMYFUNCTION("""COMPUTED_VALUE"""),80.0) -> 80 | K37: =IFERROR(__xludf.DUMMYFUNCTION("""COMPUTED_VALUE"""),13.0) -> 13 | L37: =IFERROR(__xludf.DUMMYFUNCTION("""COMPUTED_VALUE"""),"Action-Adventure") -> Action-Adventure | N37: =IFERROR(__xludf.DUMMYFUNCTION("""COMPUTED_VALUE"""),"Ubisoft games joining with price increase") -> Ubisoft games joining with price increase
A38: =IFERROR(__xludf.DUMMYFUNCTION("""COMPUTED_VALUE"""),"Assassin's Creed Rogue: Remastered") -> Assassin's Creed Rogue: Remastered | B38: =IFERROR(__xludf.DUMMYFUNCTION("""COMPUTED_VALUE"""),"Xbox / PC") -> Xbox / PC | C38: =IFERROR(__xludf.DUMMYFUNCTION("""COMPUTED_VALUE"""),"Yes") -> Yes | D38: =IFERROR(__xludf.DUMMYFUNCTION("""COMPUTED_VALUE"""),"Active") -> Active | E38: =IFERROR(__xludf.DUMMYFUNCTION("""COMPUTED_VALUE"""),45931.0) -> 45931 | G38: =IFERROR(__xludf.DUMMYFUNCTION("""COMPUTED_VALUE"""),12.166666666666666) -> 12.166667 | H38: =IFERROR(__xludf.DUMMYFUNCTION("""COMPUTED_VALUE"""),43179.0) -> 43179 | I38: =IFERROR(__xludf.DUMMYFUNCTION("""COMPUTED_VALUE"""),7.530555555555556) -> 7.5305556 | J38: =IFERROR(__xludf.DUMMYFUNCTION("""COMPUTED_VALUE"""),71.0) -> 71 | K38: =IFERROR(__xludf.DUMMYFUNCTION("""COMPUTED_VALUE"""),11.0) -> 11 | L38: =IFERROR(__xludf.DUMMYFUNCTION("""COMPUTED_VALUE"""),"Action-Adventure") -> Action-Adventure | N38: =IFERROR(__xludf.DUMMYFUNCTION("""COMPUTED_VALUE"""),"Ubisoft games joining with price increase") -> Ubisoft games joining with price increase
A39: =IFERROR(__xludf.DUMMYFUNCTION("""COMPUTED_VALUE"""),"Assassin's Creed Syndicate") -> Assassin's Creed Syndicate | B39: =IFERROR(__xludf.DUMMYFUNCTION("""COMPUTED_VALUE"""),"Xbox / PC") -> Xbox / PC | C39: =IFERROR(__xludf.DUMMYFUNCTION("""COMPUTED_VALUE"""),"Yes") -> Yes | D39: =IFERROR(__xludf.DUMMYFUNCTION("""COMPUTED_VALUE"""),"Active") -> Active | E39: =IFERROR(__xludf.DUMMYFUNCTION("""COMPUTED_VALUE"""),45931.0) -> 45931 | G39: =IFERROR(__xludf.DUMMYFUNCTION("""COMPUTED_VALUE"""),12.166666666666666) -> 12.166667 | H39: =IFERROR(__xludf.DUMMYFUNCTION("""COMPUTED_VALUE"""),42300.0) -> 42300 | I39: =IFERROR(__xludf.DUMMYFUNCTION("""COMPUTED_VALUE"""),9.938888888888888) -> 9.9388889 | J39: =IFERROR(__xludf.DUMMYFUNCTION("""COMPUTED_VALUE"""),76.0) -> 76 | K39: =IFERROR(__xludf.DUMMYFUNCTION("""COMPUTED_VALUE"""),19.0) -> 19 | L39: =IFERROR(__xludf.DUMMYFUNCTION("""COMPUTED_VALUE"""),"Action-Adventure") -> Action-Adventure | N39: =IFERROR(__xludf.DUMMYFUNCTION("""COMPUTED_VALUE"""),"Ubisoft games joining with price increase") -> Ubisoft games joining with price increase
A40: =IFERROR(__xludf.DUMMYFUNCTION("""COMPUTED_VALUE"""),"Assassin's Creed: The Ezio Collection") -> Assassin's Creed: The Ezio Collection | B40: =IFERROR(__xludf.DUMMYFUNCTION("""COMPUTED_VALUE"""),"Xbox / PC") -> Xbox / PC | C40: =IFERROR(__xludf.DUMMYFUNCTION("""COMPUTED_VALUE"""),"Yes") -> Yes | D40: =IFERROR(__xludf.DUMMYFUNCTION("""COMPUTED_VALUE"""),"Active") -> Active | E40: =IFERROR(__xludf.DUMMYFUNCTION("""COMPUTED_VALUE"""),45931.0) -> 45931 | G40: =IFERROR(__xludf.DUMMYFUNCTION("""COMPUTED_VALUE"""),12.166666666666666) -> 12.166667 | H40: =IFERROR(__xludf.DUMMYFUNCTION("""COMPUTED_VALUE"""),42689.0) -> 42689 | I40: =IFERROR(__xludf.DUMMYFUNCTION("""COMPUTED_VALUE"""),8.877777777777778) -> 8.8777778 | J40: =IFERROR(__xludf.DUMMYFUNCTION("""COMPUTED_VALUE"""),72.0) -> 72 | K40: =IFERROR(__xludf.DUMMYFUNCTION("""COMPUTED_VALUE"""),72.0) -> 72 | L40: =IFERROR(__xludf.DUMMYFUNCTION("""COMPUTED_VALUE"""),"Action-Adventure") -> Action-Adventure | N40: =IFERROR(__xludf.DUMMYFUNCTION("""COMPUTED_VALUE"""),"Ubisoft games joining with price increase") -> Ubisoft games joining with price increase
...

Sheet Tiers
A1: Game | B1: System | C1: xCloud | D1: Status | E1: Added | F1: Removed | G1: Months | H1: Release | I1: Age | J1: Metacritic | K1: Completion | L1: Genre (Giantbomb) | M1: PC | N1: Premium | O1: Essential
A2: =IFERROR(__xludf.DUMMYFUNCTION("SORT(FILTER('Master List'!A2:L1071, REGEXMATCH('Master List'!B2:B1071, ""Xbox""), NOT(REGEXMATCH('Master List'!D2:D1071, ""Removed"")) ), 10, false)"),"NHL 94 Rewind") -> NHL 94 Rewind | B2: =IFERROR(__xludf.DUMMYFUNCTION("""COMPUTED_VALUE"""),"Xbox") -> Xbox | D2: =IFERROR(__xludf.DUMMYFUNCTION("""COMPUTED_VALUE"""),"Active") -> Active | E2: =IFERROR(__xludf.DUMMYFUNCTION("""COMPUTED_VALUE"""),44168.0) -> 44168 | G2: =IFERROR(__xludf.DUMMYFUNCTION("""COMPUTED_VALUE"""),70.1) -> 70.1 | H2: =IFERROR(__xludf.DUMMYFUNCTION("""COMPUTED_VALUE"""),44134.0) -> 44134 | I2: =IFERROR(__xludf.DUMMYFUNCTION("""COMPUTED_VALUE"""),0.09166666666666666) -> 0.091666667 | J2: =IFERROR(__xludf.DUMMYFUNCTION("""COMPUTED_VALUE"""),100.0) -> 100 | K2: =IFERROR(__xludf.DUMMYFUNCTION("""COMPUTED_VALUE"""),14.5) -> 14.5 | L2: =IFERROR(__xludf.DUMMYFUNCTION("""COMPUTED_VALUE"""),"Sports") -> Sports | M2: =NOT(ISNA(VLOOKUP(A2,PC!A:A,1,FALSE))) -> FALSE | N2: =NOT(ISNA(VLOOKUP(A2,'Game Pass Premium'!A:A,1,FALSE))) -> TRUE | O2: =NOT(ISNA(VLOOKUP(A2,'Game Pass Essential'!A:A,1,FALSE))) -> FALSE
